Workbook

Sheet 01jan
M2: =TODAY() -> 46034 | W2: 29
B6: 31 | C6: 32 | D6: Celula A
B7: =IF(H16=0,0,IF(H16>=1,W17)) -> 0 | D7: 7:30 a 12:00 | F7: 13:00 a 17:18 | H7: 45659 | L7: Justificativa por não ter conseguido produzir a demanda. Preencher esta coluna quando a coluna ao lado "Faltaram", não estiver com "0"
D8: Prod. | E8: Func. | F8: =D8 -> Prod. | G8: =E8 -> Func. | H8: Qtd. | I8: Méd Func. | J8: Méd. Prod.
B9: Produtividade Média | K9: Não | T9: Data | U9: =H8 -> Qtd. | V9: =I8 -> Méd Func. | W9: Produtividade Diária
B10: Seg | C10: 45656 | H10: =D10+F10 -> 0 | I10: =IF(H10=0,0,AVERAGE(E10,G10)) -> 0 | J10: =IF(H10=0,0,H10/I10) -> 0 | K10: =IF(#REF!<>0,"Não","") -> #REF! | T10: =C10 -> 45656 | U10: =H10 -> 0 | V10: =I10 -> 0 | W10: =J10 -> 0 | X10: =IF(W10=0," ",IF(W10>1,1,))
B11: Ter | C11: =C10+1 -> 45657 | H11: =D11+F11 -> 0 | I11: =IF(H11=0,0,AVERAGE(E11,G11)) -> 0 | J11: =IF(H11=0,0,H11/I11) -> 0 | K11: =IF(#REF!<>0,"Não","") -> #REF! | T11: =C11 -> 45657 | U11: =H11 -> 0 | V11: =I11 -> 0 | W11: =J11 -> 0 | X11: =IF(W11=0," ",IF(W11>1,1,))
B12: Qua | C12: =C11+1 -> 45658 | H12: =D12+F12 -> 0 | I12: =IF(H12=0,0,AVERAGE(E12,G12)) -> 0 | J12: =IF(H12=0,0,H12/I12) -> 0 | K12: =IF(#REF!<>0,"Não","") -> #REF! | T12: =C12 -> 45658 | U12: =H12 -> 0 | V12: =I12 -> 0 | W12: =J12 -> 0 | X12: =IF(W12=0," ",IF(W12>1,1,))
B13: Qui | C13: =C12+1 -> 45659 | H13: =D13+F13 -> 0 | I13: =IF(H13=0,0,AVERAGE(E13,G13)) -> 0 | J13: =IF(H13=0,0,H13/I13) -> 0 | K13: =IF(#REF!<>0,"Não","") -> #REF! | T13: =C13 -> 45659 | U13: =H13 -> 0 | V13: =I13 -> 0 | W13: =J13 -> 0 | X13: =IF(W13=0," ",IF(W13>1,1,))
B14: Sex | C14: =C13+1 -> 45660 | H14: =D14+F14 -> 0 | I14: =IF(H14=0,0,AVERAGE(E14,G14)) -> 0 | J14: =IF(H14=0,0,H14/I14) -> 0 | K14: =IF(#REF!<>0,"Não","") -> #REF! | T14: =C14 -> 45660 | U14: =H14 -> 0 | V14: =I14 -> 0 | W14: =J14 -> 0 | X14: =IF(W14=0," ",IF(W14>1,1,))
B15: SAb | C15: =C14+1 -> 45661 | H15: =D15+F15 -> 0 | I15: =IF(H15=0,0,AVERAGE(E15,G15)) -> 0 | J15: =IF(H15=0,0,H15/I15) -> 0
B16: Total Geral | D16: =SUM(D10:D15) -> 0 | E16: =IF(SUM(E10:E15)=0,0,AVERAGE(E10:E15)) -> 0 | F16: =SUM(F10:F15) -> 0 | G16: =IF(SUM(G10:G15)=0,0,AVERAGE(G10:G15)) -> 0 | H16: =D16+F16 -> 0 | I16: =IF(H16=0,0,AVERAGE(E16,G16)) -> 0 | J16: =IF(H16=0,0,H16/I16) -> 0 | U16: =D16+F16 -> 0 | V16: =SUM(V10:V14) -> 0 | W16: =SUM(W10:W14) -> 0 | X16: =COUNT(X10:X14) -> 0
W17: =W16/X16 -> #DIV/0! | X17: =IF(W16=0,0,W17) -> 0
B18: 9 | C18: 20 | D18: Consertos de Portas
B19: =IF(H28=0,0,IF(H28>=1,W29)) -> 0 | D19: 7:30 a 12:00 | F19: 13:00 a 17:18 | H19: =H7 -> 45659 | L19: =L7 -> Justificativa por não ter conseguido produzir a demanda. Preencher esta coluna quando a coluna ao lado "Faltaram", não estiver com "0"
D20: =D8 -> Prod. | E20: =E8 -> Func. | F20: =D20 -> Prod. | G20: =E20 -> Func. | H20: =H8 -> Qtd. | I20: =I8 -> Méd Func. | J20: =J8 -> Méd. Prod.
B21: =B9 -> Produtividade Média | K21: Não | T21: =T9 -> Data | U21: =U9 -> Qtd. | V21: =V9 -> Méd Func. | W21: =W9 -> Produtividade Diária
B22: =B10 -> Seg | C22: =C10 -> 45656 | H22: =D22+F22 -> 0 | I22: =IF(H22=0,0,AVERAGE(E22,G22)) -> 0 | J22: =IF(H22=0,0,H22/I22) -> 0 | K22: =IF(#REF!<>0,"Não","") -> #REF! | T22: =C22 -> 45656 | U22: =H22 -> 0 | V22: =I22 -> 0 | W22: =J22 -> 0 | X22: =IF(W22=0," ",IF(W22>1,1,))
B23: =B11 -> Ter | C23: =C11 -> 45657 | H23: =D23+F23 -> 0 | I23: =IF(H23=0,0,AVERAGE(E23,G23)) -> 0 | J23: =IF(H23=0,0,H23/I23) -> 0 | K23: =IF(#REF!<>0,"Não","") -> #REF! | T23: =C23 -> 45657 | U23: =H23 -> 0 | V23: =I23 -> 0 | W23: =J23 -> 0 | X23: =IF(W23=0," ",IF(W23>1,1,))
B24: =B12 -> Qua | C24: =C12 -> 45658 | H24: =D24+F24 -> 0 | I24: =IF(H24=0,0,AVERAGE(E24,G24)) -> 0 | J24: =IF(H24=0,0,H24/I24) -> 0 | K24: =IF(#REF!<>0,"Não","") -> #REF! | T24: =C24 -> 45658 | U24: =H24 -> 0 | V24: =I24 -> 0 | W24: =J24 -> 0 | X24: =IF(W24=0," ",IF(W24>1,1,))
B25: =B13 -> Qui | C25: =C13 -> 45659 | H25: =D25+F25 -> 0 | I25: =IF(H25=0,0,AVERAGE(E25,G25)) -> 0 | J25: =IF(H25=0,0,H25/I25) -> 0 | K25: =IF(#REF!<>0,"Não","") -> #REF! | T25: =C25 -> 45659 | U25: =H25 -> 0 | V25: =I25 -> 0 | W25: =J25 -> 0 | X25: =IF(W25=0," ",IF(W25>1,1,))
B26: =B14 -> Sex | C26: =C14 -> 45660 | H26: =D26+F26 -> 0 | I26: =IF(H26=0,0,AVERAGE(E26,G26)) -> 0 | J26: =IF(H26=0,0,H26/I26) -> 0 | K26: =IF(#REF!<>0,"Não","") -> #REF! | T26: =C26 -> 45660 | U26: =H26 -> 0 | V26: =I26 -> 0 | W26: =J26 -> 0 | X26: =IF(W26=0," ",IF(W26>1,1,))
B27: =B15 -> SAb | C27: =C15 -> 45661 | H27: =D27+F27 -> 0 | I27: =IF(H27=0,0,AVERAGE(E27,G27)) -> 0 | J27: =IF(H27=0,0,H27/I27) -> 0
B28: =B16 -> Total Geral | D28: =SUM(D22:D27) -> 0 | E28: =IF(SUM(E22:E27)=0,0,AVERAGE(E22:E27)) -> 0 | F28: =SUM(F22:F27) -> 0 | G28: =IF(SUM(G22:G27)=0,0,AVERAGE(G22:G27)) -> 0 | H28: =D28+F28 -> 0 | I28: =AVERAGE(I22:I26) -> 0 | J28: =IF(H28=0,0,H28/I28) -> 0 | U28: =D28+F28 -> 0 | V28: =SUM(V22:V26) -> 0 | W28: =SUM(W22:W26) -> 0 | X28: =COUNT(X22:X26) -> 0
W29: =W28/X28 -> #DIV/0! | X29: =IF(W28=0,0,W29) -> 0
B30: 40 | C30: 45 | D30: Folhas Frisadas
B31: =IF(H40=0,0,IF(H40>=1,W41)) -> 0 | D31: 7:30 a 12:00 | F31: 13:00 a 17:18 | H31: =H19 -> 45659 | L31: =L19 -> Justificativa por não ter conseguido produzir a demanda. Preencher esta coluna quando a coluna ao lado "Faltaram", não estiver com "0"
D32: =D20 -> Prod. | E32: =E20 -> Func. | F32: =D32 -> Prod. | G32: =E32 -> Func. | H32: =H20 -> Qtd. | I32: =I20 -> Méd Func. | J32: =J20 -> Méd. Prod.
B33: Produtividade Média | K33: Não | T33: =T21 -> Data | U33: =U21 -> Qtd. | V33: =V21 -> Méd Func. | W33: =W21 -> Produtividade Diária
B34: =B22 -> Seg | C34: =C10 -> 45656 | H34: =D34+F34 -> 0 | I34: =IF(H34=0,0,AVERAGE(E34,G34)) -> 0 | J34: =IF(H34=0,0,H34/I34) -> 0 | K34: =IF(#REF!<>0,"Não","") -> #REF! | T34: =C34 -> 45656 | U34: =H34 -> 0 | V34: =I34 -> 0 | W34: =J34 -> 0 | X34: =IF(W34=0," ",IF(W34>1,1,))
B35: =B23 -> Ter | C35: =C11 -> 45657 | H35: =D35+F35 -> 0 | I35: =IF(H35=0,0,AVERAGE(E35,G35)) -> 0 | J35: =IF(H35=0,0,H35/I35) -> 0 | K35: =IF(#REF!<>0,"Não","") -> #REF! | T35: =C35 -> 45657 | U35: =H35 -> 0 | V35: =I35 -> 0 | W35: =J35 -> 0 | X35: =IF(W35=0," ",IF(W35>1,1,))
B36: =B24 -> Qua | C36: =C12 -> 45658 | H36: =D36+F36 -> 0 | I36: =IF(H36=0,0,AVERAGE(E36,G36)) -> 0 | J36: =IF(H36=0,0,H36/I36) -> 0 | K36: =IF(#REF!<>0,"Não","") -> #REF! | T36: =C36 -> 45658 | U36: =H36 -> 0 | V36: =I36 -> 0 | W36: =J36 -> 0 | X36: =IF(W36=0," ",IF(W36>1,1,))
B37: =B25 -> Qui | C37: =C13 -> 45659 | H37: =D37+F37 -> 0 | I37: =IF(H37=0,0,AVERAGE(E37,G37)) -> 0 | J37: =IF(H37=0,0,H37/I37) -> 0 | K37: =IF(#REF!<>0,"Não","") -> #REF! | T37: =C37 -> 45659 | U37: =H37 -> 0 | V37: =I37 -> 0 | W37: =J37 -> 0 | X37: =IF(W37=0," ",IF(W37>1,1,))
B38: =B26 -> Sex | C38: =C14 -> 45660 | H38: =D38+F38 -> 0 | I38: =IF(H38=0,0,AVERAGE(E38,G38)) -> 0 | J38: =IF(H38=0,0,H38/I38) -> 0 | K38: =IF(#REF!<>0,"Não","") -> #REF! | T38: =C38 -> 45660 | U38: =H38 -> 0 | V38: =I38 -> 0 | W38: =J38 -> 0 | X38: =IF(W38=0," ",IF(W38>1,1,))
B39: =B27 -> SAb | C39: =C15 -> 45661 | H39: =D39+F39 -> 0 | I39: =IF(H39=0,0,AVERAGE(E39,G39)) -> 0 | J39: =IF(H39=0,0,H39/I39) -> 0
B40: =B28 -> Total Geral | D40: =SUM(D34:D39) -> 0 | E40: =IF(SUM(E34:E39)=0,0,AVERAGE(E34:E39)) -> 0 | F40: =SUM(F34:F39) -> 0 | G40: =IF(SUM(G34:G39)=0,0,AVERAGE(G34:G39)) -> 0 | H40: =D40+F40 -> 0 | I40: =AVERAGE(I34:I38) -> 0 | J40: 0 | U40: =D40+F40 -> 0 | V40: =SUM(V34:V38) -> 0 | W40: =SUM(W34:W38) -> 0 | X40: =COUNT(X34:X38) -> 0
W41: =W40/X40 -> #DIV/0! | X41: =IF(W40=0,0,W41) -> 0
B42: 10 | C42: 20 | D42: Embalagens
B43: =IF(H52=0,0,IF(H52>1,W53)) -> 0 | D43: 7:30 a 12:00 | F43: 13:00 a 17:18 | H43: 45659 | L43: =L31 -> Justificativa por não ter conseguido produzir a demanda. Preencher esta coluna quando a coluna ao lado "Faltaram", não estiver com "0"
D44: =D32 -> Prod. | E44: =E32 -> Func. | F44: =F32 -> Prod. | G44: =G32 -> Func. | H44: =H32 -> Qtd. | I44: =I32 -> Méd Func. | J44: =J32 -> Méd. Prod.
...

Sheet 06jan
M2: =TODAY() -> 46034 | W2: 29
B6: ='01jan'!B6 -> 31 | C6: ='01jan'!C6 -> 32 | D6: Celula A
B7: =IF(H16=0,0,IF(H16>=1,W17)) -> 21.45 | D7: 7:30 a 12:00 | F7: 13:00 a 17:18 | H7: 45659 | L7: Justificativa por não ter conseguido produzir a demanda. Preencher esta coluna quando a coluna ao lado "Faltaram", não estiver com "0"
D8: Prod. | E8: Func. | F8: =D8 -> Prod. | G8: =E8 -> Func. | H8: Qtd. | I8: Méd Func. | J8: Méd. Prod.
B9: Produtividade Média | K9: Não | T9: Data | U9: =H8 -> Qtd. | V9: =I8 -> Méd Func. | W9: Produtividade Diária
B10: Seg | C10: ='01jan'!C15+2 -> 45663 | H10: =D10+F10 -> 0 | I10: =IF(H10=0,0,AVERAGE(E10,G10)) -> 0 | J10: =IF(H10=0,0,H10/I10) -> 0 | K10: =IF(#REF!<>0,"Não","") -> #REF! | L10: BALANÇO | T10: =C10 -> 45663 | U10: =H10 -> 0 | V10: =I10 -> 0 | W10: =J10 -> 0 | X10: =IF(W10=0," ",IF(W10>1,1,))
B11: Ter | C11: =C10+1 -> 45664 | D11: 130 | E11: 9 | F11: 122 | G11: 8.5 | H11: =D11+F11 -> 252 | I11: =IF(H11=0,0,AVERAGE(E11,G11)) -> 8.75 | J11: =IF(H11=0,0,H11/I11) -> 28.8 | K11: =IF(#REF!<>0,"Não","") -> #REF! | T11: =C11 -> 45664 | U11: =H11 -> 252 | V11: =I11 -> 8.75 | W11: =J11 -> 28.8 | X11: =IF(W11=0," ",IF(W11>1,1,)) -> 1
B12: Qua | C12: =C11+1 -> 45665 | D12: 85 | E12: 7 | F12: 76 | G12: 7 | H12: =D12+F12 -> 161 | I12: =IF(H12=0,0,AVERAGE(E12,G12)) -> 7 | J12: =IF(H12=0,0,H12/I12) -> 23 | K12: =IF(#REF!<>0,"Não","") -> #REF! | T12: =C12 -> 45665 | U12: =H12 -> 161 | V12: =I12 -> 7 | W12: =J12 -> 23 | X12: =IF(W12=0," ",IF(W12>1,1,)) -> 1
B13: Qui | C13: =C12+1 -> 45666 | D13: 39 | E13: 7 | F13: 61 | G13: 6 | H13: =D13+F13 -> 100 | I13: =IF(H13=0,0,AVERAGE(E13,G13)) -> 6.5 | J13: =IF(H13=0,0,H13/I13) -> 15.384615 | K13: =IF(#REF!<>0,"Não","") -> #REF! | T13: =C13 -> 45666 | U13: =H13 -> 100 | V13: =I13 -> 6.5 | W13: =J13 -> 15.384615 | X13: =IF(W13=0," ",IF(W13>1,1,)) -> 1
B14: Sex | C14: =C13+1 -> 45667 | D14: 69 | E14: 7 | F14: 52 | G14: 6 | H14: =D14+F14 -> 121 | I14: =IF(H14=0,0,AVERAGE(E14,G14)) -> 6.5 | J14: =IF(H14=0,0,H14/I14) -> 18.615385 | K14: =IF(#REF!<>0,"Não","") -> #REF! | T14: =C14 -> 45667 | U14: =H14 -> 121 | V14: =I14 -> 6.5 | W14: =J14 -> 18.615385 | X14: =IF(W14=0," ",IF(W14>1,1,)) -> 1
B15: SAb | C15: =C14+1 -> 45668 | H15: =D15+F15 -> 0 | I15: =IF(H15=0,0,AVERAGE(E15,G15)) -> 0 | J15: =IF(H15=0,0,H15/I15) -> 0
B16: Total Geral | D16: =SUM(D10:D15) -> 323 | E16: =IF(SUM(E10:E15)=0,0,AVERAGE(E10:E15)) -> 7.5 | F16: =SUM(F10:F15) -> 311 | G16: =IF(SUM(G10:G15)=0,0,AVERAGE(G10:G15)) -> 6.875 | H16: =D16+F16 -> 634 | I16: =IF(H16=0,0,AVERAGE(E16,G16)) -> 7.1875 | J16: =IF(H16=0,0,H16/I16) -> 88.208696 | U16: =D16+F16 -> 634 | V16: =SUM(V10:V14) -> 28.75 | W16: =SUM(W10:W14) -> 85.8 | X16: =COUNT(X10:X14) -> 4
W17: =W16/X16 -> 21.45 | X17: =IF(W16=0,0,W17) -> 21.45
B18: ='01jan'!B18 -> 9 | C18: ='01jan'!C18 -> 20 | D18: Consertos de Portas
B19: =IF(H28=0,0,IF(H28>=1,W29)) -> 7.6 | D19: 7:30 a 12:00 | F19: 13:00 a 17:18 | H19: =H7 -> 45659 | L19: =L7 -> Justificativa por não ter conseguido produzir a demanda. Preencher esta coluna quando a coluna ao lado "Faltaram", não estiver com "0"
D20: =D8 -> Prod. | E20: =E8 -> Func. | F20: =D20 -> Prod. | G20: =E20 -> Func. | H20: =H8 -> Qtd. | I20: =I8 -> Méd Func. | J20: =J8 -> Méd. Prod.
B21: =B9 -> Produtividade Média | K21: Não | T21: =T9 -> Data | U21: =U9 -> Qtd. | V21: =V9 -> Méd Func. | W21: =W9 -> Produtividade Diária
B22: =B10 -> Seg | C22: =C10 -> 45663 | D22: 3 | E22: 0.25 | F22: 4 | G22: 0.75 | H22: =D22+F22 -> 7 | I22: =IF(H22=0,0,AVERAGE(E22,G22)) -> 0.5 | J22: =IF(H22=0,0,H22/I22) -> 14 | K22: =IF(#REF!<>0,"Não","") -> #REF! | T22: =C22 -> 45663 | U22: =H22 -> 7 | V22: =I22 -> 0.5 | W22: =J22 -> 14 | X22: =IF(W22=0," ",IF(W22>1,1,)) -> 1
B23: =B11 -> Ter | C23: =C11 -> 45664 | D23: 5 | E23: 1 | F23: 5 | G23: 1 | H23: =D23+F23 -> 10 | I23: =IF(H23=0,0,AVERAGE(E23,G23)) -> 1 | J23: =IF(H23=0,0,H23/I23) -> 10 | K23: =IF(#REF!<>0,"Não","") -> #REF! | T23: =C23 -> 45664 | U23: =H23 -> 10 | V23: =I23 -> 1 | W23: =J23 -> 10 | X23: =IF(W23=0," ",IF(W23>1,1,)) -> 1
B24: =B12 -> Qua | C24: =C12 -> 45665 | D24: 3 | E24: 1 | F24: 3 | G24: 1 | H24: =D24+F24 -> 6 | I24: =IF(H24=0,0,AVERAGE(E24,G24)) -> 1 | J24: =IF(H24=0,0,H24/I24) -> 6 | K24: =IF(#REF!<>0,"Não","") -> #REF! | T24: =C24 -> 45665 | U24: =H24 -> 6 | V24: =I24 -> 1 | W24: =J24 -> 6 | X24: =IF(W24=0," ",IF(W24>1,1,)) -> 1
B25: =B13 -> Qui | C25: =C13 -> 45666 | D25: 1 | E25: 0.75 | F25: 2 | G25: 0.75 | H25: =D25+F25 -> 3 | I25: =IF(H25=0,0,AVERAGE(E25,G25)) -> 0.75 | J25: =IF(H25=0,0,H25/I25) -> 4 | K25: =IF(#REF!<>0,"Não","") -> #REF! | T25: =C25 -> 45666 | U25: =H25 -> 3 | V25: =I25 -> 0.75 | W25: =J25 -> 4 | X25: =IF(W25=0," ",IF(W25>1,1,)) -> 1
B26: =B14 -> Sex | C26: =C14 -> 45667 | D26: 2 | E26: 1 | F26: 1 | G26: 0.5 | H26: =D26+F26 -> 3 | I26: =IF(H26=0,0,AVERAGE(E26,G26)) -> 0.75 | J26: =IF(H26=0,0,H26/I26) -> 4 | K26: =IF(#REF!<>0,"Não","") -> #REF! | T26: =C26 -> 45667 | U26: =H26 -> 3 | V26: =I26 -> 0.75 | W26: =J26 -> 4 | X26: =IF(W26=0," ",IF(W26>1,1,)) -> 1
B27: =B15 -> SAb | C27: =C15 -> 45668 | H27: =D27+F27 -> 0 | I27: =IF(H27=0,0,AVERAGE(E27,G27)) -> 0 | J27: =IF(H27=0,0,H27/I27) -> 0
B28: =B16 -> Total Geral | D28: =SUM(D22:D27) -> 14 | E28: =IF(SUM(E22:E27)=0,0,AVERAGE(E22:E27)) -> 0.8 | F28: =SUM(F22:F27) -> 15 | G28: =IF(SUM(G22:G27)=0,0,AVERAGE(G22:G27)) -> 0.8 | H28: =D28+F28 -> 29 | I28: =AVERAGE(I22:I26) -> 0.8 | J28: =IF(H28=0,0,H28/I28) -> 36.25 | U28: =D28+F28 -> 29 | V28: =SUM(V22:V26) -> 4 | W28: =SUM(W22:W26) -> 38 | X28: =COUNT(X22:X26) -> 5
W29: =W28/X28 -> 7.6 | X29: =IF(W28=0,0,W29) -> 7.6
B30: ='01jan'!B30 -> 40 | C30: ='01jan'!C30 -> 45 | D30: Folhas Frisadas
B31: =IF(H40=0,0,IF(H40>=1,W41)) -> 66.4 | D31: 7:30 a 12:00 | F31: 13:00 a 17:18 | H31: =H19 -> 45659 | L31: =L19 -> Justificativa por não ter conseguido produzir a demanda. Preencher esta coluna quando a coluna ao lado "Faltaram", não estiver com "0"
D32: =D20 -> Prod. | E32: =E20 -> Func. | F32: =D32 -> Prod. | G32: =E32 -> Func. | H32: =H20 -> Qtd. | I32: =I20 -> Méd Func. | J32: =J20 -> Méd. Prod.
B33: Produtividade Média | K33: Não | T33: =T21 -> Data | U33: =U21 -> Qtd. | V33: =V21 -> Méd Func. | W33: =W21 -> Produtividade Diária
B34: =B22 -> Seg | C34: =C10 -> 45663 | H34: =D34+F34 -> 0 | I34: =IF(H34=0,0,AVERAGE(E34,G34)) -> 0 | J34: =IF(H34=0,0,H34/I34) -> 0 | K34: =IF(#REF!<>0,"Não","") -> #REF! | L34: BALANÇO | T34: =C34 -> 45663 | U34: =H34 -> 0 | V34: =I34 -> 0 | W34: =J34 -> 0 | X34: =IF(W34=0," ",IF(W34>1,1,))
B35: =B23 -> Ter | C35: =C11 -> 45664 | D35: 11 | E35: 0.25 | F35: 30 | G35: 1 | H35: =D35+F35 -> 41 | I35: =IF(H35=0,0,AVERAGE(E35,G35)) -> 0.625 | J35: =IF(H35=0,0,H35/I35) -> 65.6 | K35: =IF(#REF!<>0,"Não","") -> #REF! | T35: =C35 -> 45664 | U35: =H35 -> 41 | V35: =I35 -> 0.625 | W35: =J35 -> 65.6 | X35: =IF(W35=0," ",IF(W35>1,1,)) -> 1
B36: =B24 -> Qua | C36: =C12 -> 45665 | D36: 24 | E36: 0.75 | F36: 19 | G36: 0.75 | H36: =D36+F36 -> 43 | I36: =IF(H36=0,0,AVERAGE(E36,G36)) -> 0.75 | J36: =IF(H36=0,0,H36/I36) -> 57.333333 | K36: =IF(#REF!<>0,"Não","") -> #REF! | T36: =C36 -> 45665 | U36: =H36 -> 43 | V36: =I36 -> 0.75 | W36: =J36 -> 57.333333 | X36: =IF(W36=0," ",IF(W36>1,1,)) -> 1
B37: =B25 -> Qui | C37: =C13 -> 45666 | D37: 18 | E37: 0.75 | F37: 23 | G37: 0.75 | H37: =D37+F37 -> 41 | I37: =IF(H37=0,0,AVERAGE(E37,G37)) -> 0.75 | J37: =IF(H37=0,0,H37/I37) -> 54.666667 | K37: =IF(#REF!<>0,"Não","") -> #REF! | T37: =C37 -> 45666 | U37: =H37 -> 41 | V37: =I37 -> 0.75 | W37: =J37 -> 54.666667 | X37: =IF(W37=0," ",IF(W37>1,1,)) -> 1
B38: =B26 -> Sex | C38: =C14 -> 45667 | D38: 20 | E38: 0.5 | F38: 24 | G38: 0.5 | H38: =D38+F38 -> 44 | I38: =IF(H38=0,0,AVERAGE(E38,G38)) -> 0.5 | J38: =IF(H38=0,0,H38/I38) -> 88 | K38: =IF(#REF!<>0,"Não","") -> #REF! | T38: =C38 -> 45667 | U38: =H38 -> 44 | V38: =I38 -> 0.5 | W38: =J38 -> 88 | X38: =IF(W38=0," ",IF(W38>1,1,)) -> 1
B39: =B27 -> SAb | C39: =C15 -> 45668 | H39: =D39+F39 -> 0 | I39: =IF(H39=0,0,AVERAGE(E39,G39)) -> 0 | J39: =IF(H39=0,0,H39/I39) -> 0
B40: =B28 -> Total Geral | D40: =SUM(D34:D39) -> 73 | E40: =IF(SUM(E34:E39)=0,0,AVERAGE(E34:E39)) -> 0.5625 | F40: =SUM(F34:F39) -> 96 | G40: =IF(SUM(G34:G39)=0,0,AVERAGE(G34:G39)) -> 0.75 | H40: =D40+F40 -> 169 | I40: =AVERAGE(I34:I38) -> 0.525 | J40: 0 | U40: =D40+F40 -> 169 | V40: =SUM(V34:V38) -> 2.625 | W40: =SUM(W34:W38) -> 265.6 | X40: =COUNT(X34:X38) -> 4
W41: =W40/X40 -> 66.4 | X41: =IF(W40=0,0,W41) -> 66.4
B42: ='01jan'!B42 -> 10 | C42: ='01jan'!C42 -> 20 | D42: Embalagens
B43: =IF(H52=0,0,IF(H52>1,W53)) -> 24 | D43: 7:30 a 12:00 | F43: 13:00 a 17:18 | H43: =H31 -> 45659 | L43: =L31 -> Justificativa por não ter conseguido produzir a demanda. Preencher esta coluna quando a coluna ao lado "Faltaram", não estiver com "0"
D44: =D32 -> Prod. | E44: =E32 -> Func. | F44: =F32 -> Prod. | G44: =G32 -> Func. | H44: =H32 -> Qtd. | I44: =I32 -> Méd Func. | J44: =J32 -> Méd. Prod.
...

Sheet 13jan
M2: =TODAY() -> 46034 | W2: 29
B6: ='01jan'!B6 -> 31 | C6: ='01jan'!C6 -> 32 | D6: Celula A
B7: =IF(H16=0,0,IF(H16>=1,W17)) -> 21.630226 | D7: 7:30 a 12:00 | F7: 13:00 a 17:18 | H7: =C10 -> 45670 | L7: Justificativa por não ter conseguido produzir a demanda. Preencher esta coluna quando a coluna ao lado "Faltaram", não estiver com "0"
D8: Prod. | E8: Func. | F8: =D8 -> Prod. | G8: =E8 -> Func. | H8: Qtd. | I8: Méd Func. | J8: Méd. Prod.
B9: Produtividade Média | K9: Não | T9: Data | U9: =H8 -> Qtd. | V9: =I8 -> Méd Func. | W9: Produtividade Diária
B10: Seg | C10: ='06jan'!C15+2 -> 45670 | D10: 80 | E10: 8 | F10: 85 | G10: 7.5 | H10: =D10+F10 -> 165 | I10: =IF(H10=0,0,AVERAGE(E10,G10)) -> 7.75 | J10: =IF(H10=0,0,H10/I10) -> 21.290323 | K10: =IF(#REF!<>0,"Não","") -> #REF! | T10: =C10 -> 45670 | U10: =H10 -> 165 | V10: =I10 -> 7.75 | W10: =J10 -> 21.290323 | X10: =IF(W10=0," ",IF(W10>1,1,)) -> 1
B11: Ter | C11: =C10+1 -> 45671 | D11: 72 | E11: 7 | F11: 70 | G11: 7 | H11: =D11+F11 -> 142 | I11: =IF(H11=0,0,AVERAGE(E11,G11)) -> 7 | J11: =IF(H11=0,0,H11/I11) -> 20.285714 | K11: =IF(#REF!<>0,"Não","") -> #REF! | T11: =C11 -> 45671 | U11: =H11 -> 142 | V11: =I11 -> 7 | W11: =J11 -> 20.285714 | X11: =IF(W11=0," ",IF(W11>1,1,)) -> 1
B12: Qua | C12: =C11+1 -> 45672 | D12: 74 | E12: 7 | F12: 52 | G12: 6 | H12: =D12+F12 -> 126 | I12: =IF(H12=0,0,AVERAGE(E12,G12)) -> 6.5 | J12: =IF(H12=0,0,H12/I12) -> 19.384615 | K12: =IF(#REF!<>0,"Não","") -> #REF! | T12: =C12 -> 45672 | U12: =H12 -> 126 | V12: =I12 -> 6.5 | W12: =J12 -> 19.384615 | X12: =IF(W12=0," ",IF(W12>1,1,)) -> 1
B13: Qui | C13: =C12+1 -> 45673 | D13: 66 | E13: 7 | F13: 73 | G13: 7 | H13: =D13+F13 -> 139 | I13: =IF(H13=0,0,AVERAGE(E13,G13)) -> 7 | J13: =IF(H13=0,0,H13/I13) -> 19.857143 | K13: =IF(#REF!<>0,"Não","") -> #REF! | T13: =C13 -> 45673 | U13: =H13 -> 139 | V13: =I13 -> 7 | W13: =J13 -> 19.857143 | X13: =IF(W13=0," ",IF(W13>1,1,)) -> 1
B14: Sex | C14: =C13+1 -> 45674 | D14: 119 | E14: 8 | F14: 86 | G14: 7 | H14: =D14+F14 -> 205 | I14: =IF(H14=0,0,AVERAGE(E14,G14)) -> 7.5 | J14: =IF(H14=0,0,H14/I14) -> 27.333333 | K14: =IF(#REF!<>0,"Não","") -> #REF! | T14: =C14 -> 45674 | U14: =H14 -> 205 | V14: =I14 -> 7.5 | W14: =J14 -> 27.333333 | X14: =IF(W14=0," ",IF(W14>1,1,)) -> 1
B15: SAb | C15: =C14+1 -> 45675 | H15: =D15+F15 -> 0 | I15: =IF(H15=0,0,AVERAGE(E15,G15)) -> 0 | J15: =IF(H15=0,0,H15/I15) -> 0
B16: Total Geral | D16: =SUM(D10:D15) -> 411 | E16: =IF(SUM(E10:E15)=0,0,AVERAGE(E10:E15)) -> 7.4 | F16: =SUM(F10:F15) -> 366 | G16: =IF(SUM(G10:G15)=0,0,AVERAGE(G10:G15)) -> 6.9 | H16: =D16+F16 -> 777 | I16: =IF(H16=0,0,AVERAGE(E16,G16)) -> 7.15 | J16: =IF(H16=0,0,H16/I16) -> 108.67133 | U16: =D16+F16 -> 777 | V16: =SUM(V10:V14) -> 35.75 | W16: =SUM(W10:W14) -> 108.15113 | X16: =COUNT(X10:X14) -> 5
W17: =W16/X16 -> 21.630226 | X17: =IF(W16=0,0,W17) -> 21.630226
B18: ='01jan'!B18 -> 9 | C18: ='01jan'!C18 -> 20 | D18: Consertos de Portas
B19: =IF(H28=0,0,IF(H28>=1,W29)) -> 11.133333 | D19: 7:30 a 12:00 | F19: 13:00 a 17:18 | H19: =C22 -> 45670 | L19: =L7 -> Justificativa por não ter conseguido produzir a demanda. Preencher esta coluna quando a coluna ao lado "Faltaram", não estiver com "0"
D20: =D8 -> Prod. | E20: =E8 -> Func. | F20: =D20 -> Prod. | G20: =E20 -> Func. | H20: =H8 -> Qtd. | I20: =I8 -> Méd Func. | J20: =J8 -> Méd. Prod.
B21: =B9 -> Produtividade Média | K21: Não | T21: =T9 -> Data | U21: =U9 -> Qtd. | V21: =V9 -> Méd Func. | W21: =W9 -> Produtividade Diária
B22: =B10 -> Seg | C22: =C10 -> 45670 | D22: 3 | E22: 0.75 | F22: 1 | G22: 0.25 | H22: =D22+F22 -> 4 | I22: =IF(H22=0,0,AVERAGE(E22,G22)) -> 0.5 | J22: =IF(H22=0,0,H22/I22) -> 8 | K22: =IF(#REF!<>0,"Não","") -> #REF! | T22: =C22 -> 45670 | U22: =H22 -> 4 | V22: =I22 -> 0.5 | W22: =J22 -> 8 | X22: =IF(W22=0," ",IF(W22>1,1,)) -> 1
B23: =B11 -> Ter | C23: =C11 -> 45671 | D23: 7 | E23: 1 | F23: 6 | G23: 1 | H23: =D23+F23 -> 13 | I23: =IF(H23=0,0,AVERAGE(E23,G23)) -> 1 | J23: =IF(H23=0,0,H23/I23) -> 13 | K23: =IF(#REF!<>0,"Não","") -> #REF! | T23: =C23 -> 45671 | U23: =H23 -> 13 | V23: =I23 -> 1 | W23: =J23 -> 13 | X23: =IF(W23=0," ",IF(W23>1,1,)) -> 1
B24: =B12 -> Qua | C24: =C12 -> 45672 | D24: 9 | E24: 0.75 | F24: 4 | G24: 0.75 | H24: =D24+F24 -> 13 | I24: =IF(H24=0,0,AVERAGE(E24,G24)) -> 0.75 | J24: =IF(H24=0,0,H24/I24) -> 17.333333 | K24: =IF(#REF!<>0,"Não","") -> #REF! | T24: =C24 -> 45672 | U24: =H24 -> 13 | V24: =I24 -> 0.75 | W24: =J24 -> 17.333333 | X24: =IF(W24=0," ",IF(W24>1,1,)) -> 1
B25: =B13 -> Qui | C25: =C13 -> 45673 | D25: 3 | E25: 0.75 | F25: 4 | G25: 0.75 | H25: =D25+F25 -> 7 | I25: =IF(H25=0,0,AVERAGE(E25,G25)) -> 0.75 | J25: =IF(H25=0,0,H25/I25) -> 9.3333333 | K25: =IF(#REF!<>0,"Não","") -> #REF! | T25: =C25 -> 45673 | U25: =H25 -> 7 | V25: =I25 -> 0.75 | W25: =J25 -> 9.3333333 | X25: =IF(W25=0," ",IF(W25>1,1,)) -> 1
B26: =B14 -> Sex | C26: =C14 -> 45674 | D26: 3 | E26: 0.75 | F26: 0 | G26: 0 | H26: =D26+F26 -> 3 | I26: =IF(H26=0,0,AVERAGE(E26,G26)) -> 0.375 | J26: =IF(H26=0,0,H26/I26) -> 8 | K26: =IF(#REF!<>0,"Não","") -> #REF! | T26: =C26 -> 45674 | U26: =H26 -> 3 | V26: =I26 -> 0.375 | W26: =J26 -> 8 | X26: =IF(W26=0," ",IF(W26>1,1,)) -> 1
B27: =B15 -> SAb | C27: =C15 -> 45675 | H27: =D27+F27 -> 0 | I27: =IF(H27=0,0,AVERAGE(E27,G27)) -> 0 | J27: =IF(H27=0,0,H27/I27) -> 0
B28: =B16 -> Total Geral | D28: =SUM(D22:D27) -> 25 | E28: =IF(SUM(E22:E27)=0,0,AVERAGE(E22:E27)) -> 0.8 | F28: =SUM(F22:F27) -> 15 | G28: =IF(SUM(G22:G27)=0,0,AVERAGE(G22:G27)) -> 0.55 | H28: =D28+F28 -> 40 | I28: =AVERAGE(I22:I26) -> 0.675 | J28: =IF(H28=0,0,H28/I28) -> 59.259259 | U28: =D28+F28 -> 40 | V28: =SUM(V22:V26) -> 3.375 | W28: =SUM(W22:W26) -> 55.666667 | X28: =COUNT(X22:X26) -> 5
W29: =W28/X28 -> 11.133333 | X29: =IF(W28=0,0,W29) -> 11.133333
B30: ='01jan'!B30 -> 40 | C30: ='01jan'!C30 -> 45 | D30: Folhas Frisadas
B31: =IF(H40=0,0,IF(H40>=1,W41)) -> 44.533333 | D31: 7:30 a 12:00 | F31: 13:00 a 17:18 | H31: =C34 -> 45670 | L31: =L19 -> Justificativa por não ter conseguido produzir a demanda. Preencher esta coluna quando a coluna ao lado "Faltaram", não estiver com "0"
D32: =D20 -> Prod. | E32: =E20 -> Func. | F32: =D32 -> Prod. | G32: =E32 -> Func. | H32: =H20 -> Qtd. | I32: =I20 -> Méd Func. | J32: =J20 -> Méd. Prod.
B33: Produtividade Média | K33: Não | T33: =T21 -> Data | U33: =U21 -> Qtd. | V33: =V21 -> Méd Func. | W33: =W21 -> Produtividade Diária
B34: =B22 -> Seg | C34: =C10 -> 45670 | D34: 24 | E34: 0.75 | F34: 18 | G34: 0.75 | H34: =D34+F34 -> 42 | I34: =IF(H34=0,0,AVERAGE(E34,G34)) -> 0.75 | J34: =IF(H34=0,0,H34/I34) -> 56 | K34: =IF(#REF!<>0,"Não","") -> #REF! | T34: =C34 -> 45670 | U34: =H34 -> 42 | V34: =I34 -> 0.75 | W34: =J34 -> 56 | X34: =IF(W34=0," ",IF(W34>1,1,)) -> 1
B35: =B23 -> Ter | C35: =C11 -> 45671 | D35: 8 | E35: 0.25 | F35: 0 | G35: 0 | H35: =D35+F35 -> 8 | I35: =IF(H35=0,0,AVERAGE(E35,G35)) -> 0.125 | J35: =IF(H35=0,0,H35/I35) -> 64 | K35: =IF(#REF!<>0,"Não","") -> #REF! | T35: =C35 -> 45671 | U35: =H35 -> 8 | V35: =I35 -> 0.125 | W35: =J35 -> 64 | X35: =IF(W35=0," ",IF(W35>1,1,)) -> 1
B36: =B24 -> Qua | C36: =C12 -> 45672 | D36: 0 | E36: 0 | F36: 4 | G36: 0.75 | H36: =D36+F36 -> 4 | I36: =IF(H36=0,0,AVERAGE(E36,G36)) -> 0.375 | J36: =IF(H36=0,0,H36/I36) -> 10.666667 | K36: =IF(#REF!<>0,"Não","") -> #REF! | T36: =C36 -> 45672 | U36: =H36 -> 4 | V36: =I36 -> 0.375 | W36: =J36 -> 10.666667 | X36: =IF(W36=0," ",IF(W36>1,1,)) -> 1
B37: =B25 -> Qui | C37: =C13 -> 45673 | D37: 15 | E37: 0.75 | F37: 24 | G37: 0.75 | H37: =D37+F37 -> 39 | I37: =IF(H37=0,0,AVERAGE(E37,G37)) -> 0.75 | J37: =IF(H37=0,0,H37/I37) -> 52 | K37: =IF(#REF!<>0,"Não","") -> #REF! | T37: =C37 -> 45673 | U37: =H37 -> 39 | V37: =I37 -> 0.75 | W37: =J37 -> 52 | X37: =IF(W37=0," ",IF(W37>1,1,)) -> 1
B38: =B26 -> Sex | C38: =C14 -> 45674 | D38: 20 | E38: 1 | F38: 0 | G38: 0 | H38: =D38+F38 -> 20 | I38: =IF(H38=0,0,AVERAGE(E38,G38)) -> 0.5 | J38: =IF(H38=0,0,H38/I38) -> 40 | K38: =IF(#REF!<>0,"Não","") -> #REF! | T38: =C38 -> 45674 | U38: =H38 -> 20 | V38: =I38 -> 0.5 | W38: =J38 -> 40 | X38: =IF(W38=0," ",IF(W38>1,1,)) -> 1
B39: =B27 -> SAb | C39: =C15 -> 45675 | H39: =D39+F39 -> 0 | I39: =IF(H39=0,0,AVERAGE(E39,G39)) -> 0 | J39: =IF(H39=0,0,H39/I39) -> 0
B40: =B28 -> Total Geral | D40: =SUM(D34:D39) -> 67 | E40: =IF(SUM(E34:E39)=0,0,AVERAGE(E34:E39)) -> 0.55 | F40: =SUM(F34:F39) -> 46 | G40: =IF(SUM(G34:G39)=0,0,AVERAGE(G34:G39)) -> 0.45 | H40: =D40+F40 -> 113 | I40: =AVERAGE(I34:I38) -> 0.5 | J40: 0 | U40: =D40+F40 -> 113 | V40: =SUM(V34:V38) -> 2.5 | W40: =SUM(W34:W38) -> 222.66667 | X40: =COUNT(X34:X38) -> 5
W41: =W40/X40 -> 44.533333 | X41: =IF(W40=0,0,W41) -> 44.533333
B42: ='01jan'!B42 -> 10 | C42: ='01jan'!C42 -> 20 | D42: Embalagens
B43: =IF(H52=0,0,IF(H52>1,W53)) -> 42.857143 | D43: 7:30 a 12:00 | F43: 13:00 a 17:18 | H43: 45293 | L43: =L31 -> Justificativa por não ter conseguido produzir a demanda. Preencher esta coluna quando a coluna ao lado "Faltaram", não estiver com "0"
D44: =D32 -> Prod. | E44: =E32 -> Func. | F44: =F32 -> Prod. | G44: =G32 -> Func. | H44: =H32 -> Qtd. | I44: =I32 -> Méd Func. | J44: =J32 -> Méd. Prod.
...

Sheet 20jan
M2: =TODAY() -> 46034 | W2: 29
B6: ='01jan'!B6 -> 31 | C6: ='01jan'!C6 -> 32 | D6: Celula A
B7: =IF(H16=0,0,IF(H16>=1,W17)) -> 24.807792 | D7: 7:30 a 12:00 | F7: 13:00 a 17:18 | H7: =C10 -> 45677 | L7: Justificativa por não ter conseguido produzir a demanda. Preencher esta coluna quando a coluna ao lado "Faltaram", não estiver com "0"
D8: Prod. | E8: Func. | F8: =D8 -> Prod. | G8: =E8 -> Func. | H8: Qtd. | I8: Méd Func. | J8: Méd. Prod.
B9: Produtividade Média | K9: Não | T9: Data | U9: =H8 -> Qtd. | V9: =I8 -> Méd Func. | W9: Produtividade Diária
B10: Seg | C10: ='13jan'!C15+2 -> 45677 | D10: 122 | E10: 7 | F10: 80 | G10: 7 | H10: =D10+F10 -> 202 | I10: =IF(H10=0,0,AVERAGE(E10,G10)) -> 7 | J10: =IF(H10=0,0,H10/I10) -> 28.857143 | K10: =IF(#REF!<>0,"Não","") -> #REF! | T10: =C10 -> 45677 | U10: =H10 -> 202 | V10: =I10 -> 7 | W10: =J10 -> 28.857143 | X10: =IF(W10=0," ",IF(W10>1,1,)) -> 1
B11: Ter | C11: =C10+1 -> 45678 | D11: 58 | E11: 5 | F11: 62 | G11: 5 | H11: =D11+F11 -> 120 | I11: =IF(H11=0,0,AVERAGE(E11,G11)) -> 5 | J11: =IF(H11=0,0,H11/I11) -> 24 | K11: =IF(#REF!<>0,"Não","") -> #REF! | T11: =C11 -> 45678 | U11: =H11 -> 120 | V11: =I11 -> 5 | W11: =J11 -> 24 | X11: =IF(W11=0," ",IF(W11>1,1,)) -> 1
B12: Qua | C12: =C11+1 -> 45679 | D12: 86 | E12: 7 | F12: 79 | G12: 7 | H12: =D12+F12 -> 165 | I12: =IF(H12=0,0,AVERAGE(E12,G12)) -> 7 | J12: =IF(H12=0,0,H12/I12) -> 23.571429 | K12: =IF(#REF!<>0,"Não","") -> #REF! | T12: =C12 -> 45679 | U12: =H12 -> 165 | V12: =I12 -> 7 | W12: =J12 -> 23.571429 | X12: =IF(W12=0," ",IF(W12>1,1,)) -> 1
B13: Qui | C13: =C12+1 -> 45680 | D13: 88 | E13: 7 | F13: 90 | G13: 7 | H13: =D13+F13 -> 178 | I13: =IF(H13=0,0,AVERAGE(E13,G13)) -> 7 | J13: =IF(H13=0,0,H13/I13) -> 25.428571 | K13: =IF(#REF!<>0,"Não","") -> #REF! | T13: =C13 -> 45680 | U13: =H13 -> 178 | V13: =I13 -> 7 | W13: =J13 -> 25.428571 | X13: =IF(W13=0," ",IF(W13>1,1,)) -> 1
B14: Sex | C14: =C13+1 -> 45681 | D14: 72 | E14: 6 | F14: 50 | G14: 5 | H14: =D14+F14 -> 122 | I14: =IF(H14=0,0,AVERAGE(E14,G14)) -> 5.5 | J14: =IF(H14=0,0,H14/I14) -> 22.181818 | K14: =IF(#REF!<>0,"Não","") -> #REF! | T14: =C14 -> 45681 | U14: =H14 -> 122 | V14: =I14 -> 5.5 | W14: =J14 -> 22.181818 | X14: =IF(W14=0," ",IF(W14>1,1,)) -> 1
B15: SAb | C15: =C14+1 -> 45682 | D15: 37 | E15: 4 | F15: 30 | G15: 4 | H15: =D15+F15 -> 67 | I15: =IF(H15=0,0,AVERAGE(E15,G15)) -> 4 | J15: =IF(H15=0,0,H15/I15) -> 16.75
B16: Total Geral | D16: =SUM(D10:D15) -> 463 | E16: =IF(SUM(E10:E15)=0,0,AVERAGE(E10:E15)) -> 6 | F16: =SUM(F10:F15) -> 391 | G16: =IF(SUM(G10:G15)=0,0,AVERAGE(G10:G15)) -> 5.8333333 | H16: =D16+F16 -> 854 | I16: =IF(H16=0,0,AVERAGE(E16,G16)) -> 5.9166667 | J16: =IF(H16=0,0,H16/I16) -> 144.33803 | U16: =D16+F16 -> 854 | V16: =SUM(V10:V14) -> 31.5 | W16: =SUM(W10:W14) -> 124.03896 | X16: =COUNT(X10:X14) -> 5
W17: =W16/X16 -> 24.807792 | X17: =IF(W16=0,0,W17) -> 24.807792
B18: ='01jan'!B18 -> 9 | C18: ='01jan'!C18 -> 20 | D18: Consertos de Portas
B19: =IF(H28=0,0,IF(H28>=1,W29)) -> 10.377143 | D19: 7:30 a 12:00 | F19: 13:00 a 17:18 | H19: =C22 -> 45677 | L19: =L7 -> Justificativa por não ter conseguido produzir a demanda. Preencher esta coluna quando a coluna ao lado "Faltaram", não estiver com "0"
D20: =D8 -> Prod. | E20: =E8 -> Func. | F20: =D20 -> Prod. | G20: =E20 -> Func. | H20: =H8 -> Qtd. | I20: =I8 -> Méd Func. | J20: =J8 -> Méd. Prod.
B21: =B9 -> Produtividade Média | K21: Não | T21: =T9 -> Data | U21: =U9 -> Qtd. | V21: =V9 -> Méd Func. | W21: =W9 -> Produtividade Diária
B22: =B10 -> Seg | C22: =C10 -> 45677 | D22: 3 | E22: 1 | F22: 3 | G22: 0.5 | H22: =D22+F22 -> 6 | I22: =IF(H22=0,0,AVERAGE(E22,G22)) -> 0.75 | J22: =IF(H22=0,0,H22/I22) -> 8 | K22: =IF(#REF!<>0,"Não","") -> #REF! | T22: =C22 -> 45677 | U22: =H22 -> 6 | V22: =I22 -> 0.75 | W22: =J22 -> 8 | X22: =IF(W22=0," ",IF(W22>1,1,)) -> 1
B23: =B11 -> Ter | C23: =C11 -> 45678 | D23: 5 | E23: 1 | F23: 4 | G23: 0.75 | H23: =D23+F23 -> 9 | I23: =IF(H23=0,0,AVERAGE(E23,G23)) -> 0.875 | J23: =IF(H23=0,0,H23/I23) -> 10.285714 | K23: =IF(#REF!<>0,"Não","") -> #REF! | T23: =C23 -> 45678 | U23: =H23 -> 9 | V23: =I23 -> 0.875 | W23: =J23 -> 10.285714 | X23: =IF(W23=0," ",IF(W23>1,1,)) -> 1
B24: =B12 -> Qua | C24: =C12 -> 45679 | D24: 5 | E24: 0.5 | F24: 2 | G24: 0.5 | H24: =D24+F24 -> 7 | I24: =IF(H24=0,0,AVERAGE(E24,G24)) -> 0.5 | J24: =IF(H24=0,0,H24/I24) -> 14 | K24: =IF(#REF!<>0,"Não","") -> #REF! | T24: =C24 -> 45679 | U24: =H24 -> 7 | V24: =I24 -> 0.5 | W24: =J24 -> 14 | X24: =IF(W24=0," ",IF(W24>1,1,)) -> 1
B25: =B13 -> Qui | C25: =C13 -> 45680 | D25: 2 | E25: 0.5 | F25: 3 | G25: 0.5 | H25: =D25+F25 -> 5 | I25: =IF(H25=0,0,AVERAGE(E25,G25)) -> 0.5 | J25: =IF(H25=0,0,H25/I25) -> 10 | K25: =IF(#REF!<>0,"Não","") -> #REF! | T25: =C25 -> 45680 | U25: =H25 -> 5 | V25: =I25 -> 0.5 | W25: =J25 -> 10 | X25: =IF(W25=0," ",IF(W25>1,1,)) -> 1
B26: =B14 -> Sex | C26: =C14 -> 45681 | D26: 3 | E26: 0.75 | F26: 3 | G26: 0.5 | H26: =D26+F26 -> 6 | I26: =IF(H26=0,0,AVERAGE(E26,G26)) -> 0.625 | J26: =IF(H26=0,0,H26/I26) -> 9.6 | K26: =IF(#REF!<>0,"Não","") -> #REF! | T26: =C26 -> 45681 | U26: =H26 -> 6 | V26: =I26 -> 0.625 | W26: =J26 -> 9.6 | X26: =IF(W26=0," ",IF(W26>1,1,)) -> 1
B27: =B15 -> SAb | C27: =C15 -> 45682 | H27: =D27+F27 -> 0 | I27: =IF(H27=0,0,AVERAGE(E27,G27)) -> 0 | J27: =IF(H27=0,0,H27/I27) -> 0
B28: =B16 -> Total Geral | D28: =SUM(D22:D27) -> 18 | E28: =IF(SUM(E22:E27)=0,0,AVERAGE(E22:E27)) -> 0.75 | F28: =SUM(F22:F27) -> 15 | G28: =IF(SUM(G22:G27)=0,0,AVERAGE(G22:G27)) -> 0.55 | H28: =D28+F28 -> 33 | I28: =AVERAGE(I22:I26) -> 0.65 | J28: =IF(H28=0,0,H28/I28) -> 50.769231 | U28: =D28+F28 -> 33 | V28: =SUM(V22:V26) -> 3.25 | W28: =SUM(W22:W26) -> 51.885714 | X28: =COUNT(X22:X26) -> 5
W29: =W28/X28 -> 10.377143 | X29: =IF(W28=0,0,W29) -> 10.377143
B30: ='01jan'!B30 -> 40 | C30: ='01jan'!C30 -> 45 | D30: Folhas Frisadas
B31: =IF(H40=0,0,IF(H40>=1,W41)) -> 51.59619 | D31: 7:30 a 12:00 | F31: 13:00 a 17:18 | H31: =C34 -> 45677 | L31: =L19 -> Justificativa por não ter conseguido produzir a demanda. Preencher esta coluna quando a coluna ao lado "Faltaram", não estiver com "0"
D32: =D20 -> Prod. | E32: =E20 -> Func. | F32: =D32 -> Prod. | G32: =E32 -> Func. | H32: =H20 -> Qtd. | I32: =I20 -> Méd Func. | J32: =J20 -> Méd. Prod.
B33: Produtividade Média | K33: Não | T33: =T21 -> Data | U33: =U21 -> Qtd. | V33: =V21 -> Méd Func. | W33: =W21 -> Produtividade Diária
B34: =B22 -> Seg | C34: =C10 -> 45677 | D34: 19 | E34: 0.5 | F34: 17 | G34: 0.5 | H34: =D34+F34 -> 36 | I34: =IF(H34=0,0,AVERAGE(E34,G34)) -> 0.5 | J34: =IF(H34=0,0,H34/I34) -> 72 | K34: =IF(#REF!<>0,"Não","") -> #REF! | T34: =C34 -> 45677 | U34: =H34 -> 36 | V34: =I34 -> 0.5 | W34: =J34 -> 72 | X34: =IF(W34=0," ",IF(W34>1,1,)) -> 1
B35: =B23 -> Ter | C35: =C11 -> 45678 | D35: 1 | E35: 0.25 | F35: 15 | G35: 1 | H35: =D35+F35 -> 16 | I35: =IF(H35=0,0,AVERAGE(E35,G35)) -> 0.625 | J35: =IF(H35=0,0,H35/I35) -> 25.6 | K35: =IF(#REF!<>0,"Não","") -> #REF! | L35: 2 horas arrumando o gabarito do friso | T35: =C35 -> 45678 | U35: =H35 -> 16 | V35: =I35 -> 0.625 | W35: =J35 -> 25.6 | X35: =IF(W35=0," ",IF(W35>1,1,)) -> 1
B36: =B24 -> Qua | C36: =C12 -> 45679 | D36: 18 | E36: 0.75 | F36: 27 | G36: 1 | H36: =D36+F36 -> 45 | I36: =IF(H36=0,0,AVERAGE(E36,G36)) -> 0.875 | J36: =IF(H36=0,0,H36/I36) -> 51.428571 | K36: =IF(#REF!<>0,"Não","") -> #REF! | T36: =C36 -> 45679 | U36: =H36 -> 45 | V36: =I36 -> 0.875 | W36: =J36 -> 51.428571 | X36: =IF(W36=0," ",IF(W36>1,1,)) -> 1
B37: =B25 -> Qui | C37: =C13 -> 45680 | D37: 22 | E37: 0.75 | F37: 0 | G37: 0 | H37: =D37+F37 -> 22 | I37: =IF(H37=0,0,AVERAGE(E37,G37)) -> 0.375 | J37: =IF(H37=0,0,H37/I37) -> 58.666667 | K37: =IF(#REF!<>0,"Não","") -> #REF! | T37: =C37 -> 45680 | U37: =H37 -> 22 | V37: =I37 -> 0.375 | W37: =J37 -> 58.666667 | X37: =IF(W37=0," ",IF(W37>1,1,)) -> 1
B38: =B26 -> Sex | C38: =C14 -> 45681 | D38: 21 | E38: 1 | F38: 23 | G38: 0.75 | H38: =D38+F38 -> 44 | I38: =IF(H38=0,0,AVERAGE(E38,G38)) -> 0.875 | J38: =IF(H38=0,0,H38/I38) -> 50.285714 | K38: =IF(#REF!<>0,"Não","") -> #REF! | T38: =C38 -> 45681 | U38: =H38 -> 44 | V38: =I38 -> 0.875 | W38: =J38 -> 50.285714 | X38: =IF(W38=0," ",IF(W38>1,1,)) -> 1
B39: =B27 -> SAb | C39: =C15 -> 45682 | H39: =D39+F39 -> 0 | I39: =IF(H39=0,0,AVERAGE(E39,G39)) -> 0 | J39: =IF(H39=0,0,H39/I39) -> 0
B40: =B28 -> Total Geral | D40: =SUM(D34:D39) -> 81 | E40: =IF(SUM(E34:E39)=0,0,AVERAGE(E34:E39)) -> 0.65 | F40: =SUM(F34:F39) -> 82 | G40: =IF(SUM(G34:G39)=0,0,AVERAGE(G34:G39)) -> 0.65 | H40: =D40+F40 -> 163 | I40: =AVERAGE(I34:I38) -> 0.65 | J40: 0 | U40: =D40+F40 -> 163 | V40: =SUM(V34:V38) -> 3.25 | W40: =SUM(W34:W38) -> 257.98095 | X40: =COUNT(X34:X38) -> 5
W41: =W40/X40 -> 51.59619 | X41: =IF(W40=0,0,W41) -> 51.59619
B42: ='01jan'!B42 -> 10 | C42: ='01jan'!C42 -> 20 | D42: Embalagens
B43: =IF(H52=0,0,IF(H52>1,W53)) -> 42 | D43: 7:30 a 12:00 | F43: 13:00 a 17:18 | H43: =C46 -> 45677 | L43: =L31 -> Justificativa por não ter conseguido produzir a demanda. Preencher esta coluna quando a coluna ao lado "Faltaram", não estiver com "0"
D44: =D32 -> Prod. | E44: =E32 -> Func. | F44: =F32 -> Prod. | G44: =G32 -> Func. | H44: =H32 -> Qtd. | I44: =I32 -> Méd Func. | J44: =J32 -> Méd. Prod.
...

Sheet 27jan
M2: =TODAY() -> 46034 | W2: 29
B6: ='01jan'!B6 -> 31 | C6: ='01jan'!C6 -> 32 | D6: Celula A
B7: =IF(H16=0,0,IF(H16>=1,W17)) -> 28.256331 | D7: 7:30 a 12:00 | F7: 13:00 a 17:18 | H7: =C10 -> 45684 | L7: Justificativa por não ter conseguido produzir a demanda. Preencher esta coluna quando a coluna ao lado "Faltaram", não estiver com "0"
D8: Prod. | E8: Func. | F8: =D8 -> Prod. | G8: =E8 -> Func. | H8: Qtd. | I8: Méd Func. | J8: Méd. Prod.
B9: Produtividade Média | K9: Não | T9: Data | U9: =H8 -> Qtd. | V9: =I8 -> Méd Func. | W9: Produtividade Diária
B10: Seg | C10: ='20jan'!C15+2 -> 45684 | D10: 49 | E10: 6.5 | F10: 138 | G10: 6.5 | H10: =D10+F10 -> 187 | I10: =IF(H10=0,0,AVERAGE(E10,G10)) -> 6.5 | J10: =IF(H10=0,0,H10/I10) -> 28.769231 | K10: =IF(#REF!<>0,"Não","") -> #REF! | T10: =C10 -> 45684 | U10: =H10 -> 187 | V10: =I10 -> 6.5 | W10: =J10 -> 28.769231 | X10: =IF(W10=0," ",IF(W10>1,1,)) -> 1
B11: Ter | C11: =C10+1 -> 45685 | D11: 68 | E11: 4 | F11: 78 | G11: 6.5 | H11: =D11+F11 -> 146 | I11: =IF(H11=0,0,AVERAGE(E11,G11)) -> 5.25 | J11: =IF(H11=0,0,H11/I11) -> 27.809524 | K11: =IF(#REF!<>0,"Não","") -> #REF! | T11: =C11 -> 45685 | U11: =H11 -> 146 | V11: =I11 -> 5.25 | W11: =J11 -> 27.809524 | X11: =IF(W11=0," ",IF(W11>1,1,)) -> 1
B12: Qua | C12: =C11+1 -> 45686 | D12: 68 | E12: 6 | F12: 75 | G12: 5.5 | H12: =D12+F12 -> 143 | I12: =IF(H12=0,0,AVERAGE(E12,G12)) -> 5.75 | J12: =IF(H12=0,0,H12/I12) -> 24.869565 | K12: =IF(#REF!<>0,"Não","") -> #REF! | T12: =C12 -> 45686 | U12: =H12 -> 143 | V12: =I12 -> 5.75 | W12: =J12 -> 24.869565 | X12: =IF(W12=0," ",IF(W12>1,1,)) -> 1
B13: Qui | C13: =C12+1 -> 45687 | D13: 87 | E13: 6 | F13: 87 | G13: 6 | H13: =D13+F13 -> 174 | I13: =IF(H13=0,0,AVERAGE(E13,G13)) -> 6 | J13: =IF(H13=0,0,H13/I13) -> 29 | K13: =IF(#REF!<>0,"Não","") -> #REF! | T13: =C13 -> 45687 | U13: =H13 -> 174 | V13: =I13 -> 6 | W13: =J13 -> 29 | X13: =IF(W13=0," ",IF(W13>1,1,)) -> 1
B14: Sex | C14: =C13+1 -> 45688 | D14: 81 | E14: 6 | F14: 104 | G14: 6 | H14: =D14+F14 -> 185 | I14: =IF(H14=0,0,AVERAGE(E14,G14)) -> 6 | J14: =IF(H14=0,0,H14/I14) -> 30.833333 | K14: =IF(#REF!<>0,"Não","") -> #REF! | T14: =C14 -> 45688 | U14: =H14 -> 185 | V14: =I14 -> 6 | W14: =J14 -> 30.833333 | X14: =IF(W14=0," ",IF(W14>1,1,)) -> 1
B15: SAb | C15: =C14+1 -> 45689 | H15: =D15+F15 -> 0 | I15: =IF(H15=0,0,AVERAGE(E15,G15)) -> 0 | J15: =IF(H15=0,0,H15/I15) -> 0
B16: Total Geral | D16: =SUM(D10:D15) -> 353 | E16: =IF(SUM(E10:E15)=0,0,AVERAGE(E10:E15)) -> 5.7 | F16: =SUM(F10:F15) -> 482 | G16: =IF(SUM(G10:G15)=0,0,AVERAGE(G10:G15)) -> 6.1 | H16: =D16+F16 -> 835 | I16: =IF(H16=0,0,AVERAGE(E16,G16)) -> 5.9 | J16: =IF(H16=0,0,H16/I16) -> 141.52542 | U16: =D16+F16 -> 835 | V16: =SUM(V10:V14) -> 29.5 | W16: =SUM(W10:W14) -> 141.28165 | X16: =COUNT(X10:X14) -> 5
W17: =W16/X16 -> 28.256331 | X17: =IF(W16=0,0,W17) -> 28.256331
B18: ='01jan'!B18 -> 9 | C18: ='01jan'!C18 -> 20 | D18: Consertos de Portas
B19: =IF(H28=0,0,IF(H28>=1,W29)) -> 11.300202 | D19: 7:30 a 12:00 | F19: 13:00 a 17:18 | H19: =C22 -> 45684 | L19: =L7 -> Justificativa por não ter conseguido produzir a demanda. Preencher esta coluna quando a coluna ao lado "Faltaram", não estiver com "0"
D20: =D8 -> Prod. | E20: =E8 -> Func. | F20: =D20 -> Prod. | G20: =E20 -> Func. | H20: =H8 -> Qtd. | I20: =I8 -> Méd Func. | J20: =J8 -> Méd. Prod.
B21: =B9 -> Produtividade Média | K21: Não | T21: =T9 -> Data | U21: =U9 -> Qtd. | V21: =V9 -> Méd Func. | W21: =W9 -> Produtividade Diária
B22: =B10 -> Seg | C22: =C10 -> 45684 | D22: 13 | E22: 1.5 | F22: 6 | G22: 0.75 | H22: =D22+F22 -> 19 | I22: =IF(H22=0,0,AVERAGE(E22,G22)) -> 1.125 | J22: =IF(H22=0,0,H22/I22) -> 16.888889 | K22: =IF(#REF!<>0,"Não","") -> #REF! | T22: =C22 -> 45684 | U22: =H22 -> 19 | V22: =I22 -> 1.125 | W22: =J22 -> 16.888889 | X22: =IF(W22=0," ",IF(W22>1,1,)) -> 1
B23: =B11 -> Ter | C23: =C11 -> 45685 | D23: 2 | E23: 0.5 | F23: 6 | G23: 0.75 | H23: =D23+F23 -> 8 | I23: =IF(H23=0,0,AVERAGE(E23,G23)) -> 0.625 | J23: =IF(H23=0,0,H23/I23) -> 12.8 | K23: =IF(#REF!<>0,"Não","") -> #REF! | T23: =C23 -> 45685 | U23: =H23 -> 8 | V23: =I23 -> 0.625 | W23: =J23 -> 12.8 | X23: =IF(W23=0," ",IF(W23>1,1,)) -> 1
B24: =B12 -> Qua | C24: =C12 -> 45686 | D24: 3 | E24: 0.5 | F24: 3 | G24: 0.75 | H24: =D24+F24 -> 6 | I24: =IF(H24=0,0,AVERAGE(E24,G24)) -> 0.625 | J24: =IF(H24=0,0,H24/I24) -> 9.6 | K24: =IF(#REF!<>0,"Não","") -> #REF! | T24: =C24 -> 45686 | U24: =H24 -> 6 | V24: =I24 -> 0.625 | W24: =J24 -> 9.6 | X24: =IF(W24=0," ",IF(W24>1,1,)) -> 1
B25: =B13 -> Qui | C25: =C13 -> 45687 | D25: 4 | E25: 1.75 | F25: 5 | G25: 1 | H25: =D25+F25 -> 9 | I25: =IF(H25=0,0,AVERAGE(E25,G25)) -> 1.375 | J25: =IF(H25=0,0,H25/I25) -> 6.5454545 | K25: =IF(#REF!<>0,"Não","") -> #REF! | T25: =C25 -> 45687 | U25: =H25 -> 9 | V25: =I25 -> 1.375 | W25: =J25 -> 6.5454545 | X25: =IF(W25=0," ",IF(W25>1,1,)) -> 1
B26: =B14 -> Sex | C26: =C14 -> 45688 | D26: 4 | E26: 0.5 | F26: 4 | G26: 1 | H26: =D26+F26 -> 8 | I26: =IF(H26=0,0,AVERAGE(E26,G26)) -> 0.75 | J26: =IF(H26=0,0,H26/I26) -> 10.666667 | K26: =IF(#REF!<>0,"Não","") -> #REF! | T26: =C26 -> 45688 | U26: =H26 -> 8 | V26: =I26 -> 0.75 | W26: =J26 -> 10.666667 | X26: =IF(W26=0," ",IF(W26>1,1,)) -> 1
B27: =B15 -> SAb | C27: =C15 -> 45689 | H27: =D27+F27 -> 0 | I27: =IF(H27=0,0,AVERAGE(E27,G27)) -> 0 | J27: =IF(H27=0,0,H27/I27) -> 0
B28: =B16 -> Total Geral | D28: =SUM(D22:D27) -> 26 | E28: =IF(SUM(E22:E27)=0,0,AVERAGE(E22:E27)) -> 0.95 | F28: =SUM(F22:F27) -> 24 | G28: =IF(SUM(G22:G27)=0,0,AVERAGE(G22:G27)) -> 0.85 | H28: =D28+F28 -> 50 | I28: =AVERAGE(I22:I26) -> 0.9 | J28: =IF(H28=0,0,H28/I28) -> 55.555556 | U28: =D28+F28 -> 50 | V28: =SUM(V22:V26) -> 4.5 | W28: =SUM(W22:W26) -> 56.50101 | X28: =COUNT(X22:X26) -> 5
W29: =W28/X28 -> 11.300202 | X29: =IF(W28=0,0,W29) -> 11.300202
B30: ='01jan'!B30 -> 40 | C30: ='01jan'!C30 -> 45 | D30: Folhas Frisadas
B31: =IF(H40=0,0,IF(H40>=1,W41)) -> 57.8 | D31: 7:30 a 12:00 | F31: 13:00 a 17:18 | H31: 45293 | L31: =L19 -> Justificativa por não ter conseguido produzir a demanda. Preencher esta coluna quando a coluna ao lado "Faltaram", não estiver com "0"
D32: =D20 -> Prod. | E32: =E20 -> Func. | F32: =D32 -> Prod. | G32: =E32 -> Func. | H32: =H20 -> Qtd. | I32: =I20 -> Méd Func. | J32: =J20 -> Méd. Prod.
B33: Produtividade Média | K33: Não | T33: =T21 -> Data | U33: =U21 -> Qtd. | V33: =V21 -> Méd Func. | W33: =W21 -> Produtividade Diária
B34: =B22 -> Seg | C34: =C10 -> 45684 | D34: 25 | E34: 1 | F34: 24 | G34: 0.75 | H34: =D34+F34 -> 49 | I34: =IF(H34=0,0,AVERAGE(E34,G34)) -> 0.875 | J34: =IF(H34=0,0,H34/I34) -> 56 | K34: =IF(#REF!<>0,"Não","") -> #REF! | T34: =C34 -> 45684 | U34: =H34 -> 49 | V34: =I34 -> 0.875 | W34: =J34 -> 56 | X34: =IF(W34=0," ",IF(W34>1,1,)) -> 1
B35: =B23 -> Ter | C35: =C11 -> 45685 | D35: 5 | E35: 0.25 | F35: 6 | G35: 0.25 | H35: =D35+F35 -> 11 | I35: =IF(H35=0,0,AVERAGE(E35,G35)) -> 0.25 | J35: =IF(H35=0,0,H35/I35) -> 44 | K35: =IF(#REF!<>0,"Não","") -> #REF! | T35: =C35 -> 45685 | U35: =H35 -> 11 | V35: =I35 -> 0.25 | W35: =J35 -> 44 | X35: =IF(W35=0," ",IF(W35>1,1,)) -> 1
B36: =B24 -> Qua | C36: =C12 -> 45686 | D36: 25 | E36: 1 | F36: 35 | G36: 1 | H36: =D36+F36 -> 60 | I36: =IF(H36=0,0,AVERAGE(E36,G36)) -> 1 | J36: =IF(H36=0,0,H36/I36) -> 60 | K36: =IF(#REF!<>0,"Não","") -> #REF! | T36: =C36 -> 45686 | U36: =H36 -> 60 | V36: =I36 -> 1 | W36: =J36 -> 60 | X36: =IF(W36=0," ",IF(W36>1,1,)) -> 1
B37: =B25 -> Qui | C37: =C13 -> 45687 | D37: 41 | E37: 1 | F37: 40 | G37: 1 | H37: =D37+F37 -> 81 | I37: =IF(H37=0,0,AVERAGE(E37,G37)) -> 1 | J37: =IF(H37=0,0,H37/I37) -> 81 | K37: =IF(#REF!<>0,"Não","") -> #REF! | T37: =C37 -> 45687 | U37: =H37 -> 81 | V37: =I37 -> 1 | W37: =J37 -> 81 | X37: =IF(W37=0," ",IF(W37>1,1,)) -> 1
B38: =B26 -> Sex | C38: =C14 -> 45688 | D38: 12 | E38: 0.75 | F38: 30 | G38: 1 | H38: =D38+F38 -> 42 | I38: =IF(H38=0,0,AVERAGE(E38,G38)) -> 0.875 | J38: =IF(H38=0,0,H38/I38) -> 48 | K38: =IF(#REF!<>0,"Não","") -> #REF! | T38: =C38 -> 45688 | U38: =H38 -> 42 | V38: =I38 -> 0.875 | W38: =J38 -> 48 | X38: =IF(W38=0," ",IF(W38>1,1,)) -> 1
B39: =B27 -> SAb | C39: =C15 -> 45689 | H39: =D39+F39 -> 0 | I39: =IF(H39=0,0,AVERAGE(E39,G39)) -> 0 | J39: =IF(H39=0,0,H39/I39) -> 0
B40: =B28 -> Total Geral | D40: =SUM(D34:D39) -> 108 | E40: =IF(SUM(E34:E39)=0,0,AVERAGE(E34:E39)) -> 0.8 | F40: =SUM(F34:F39) -> 135 | G40: =IF(SUM(G34:G39)=0,0,AVERAGE(G34:G39)) -> 0.8 | H40: =D40+F40 -> 243 | I40: =AVERAGE(I34:I38) -> 0.8 | J40: 0 | U40: =D40+F40 -> 243 | V40: =SUM(V34:V38) -> 4 | W40: =SUM(W34:W38) -> 289 | X40: =COUNT(X34:X38) -> 5
W41: =W40/X40 -> 57.8 | X41: =IF(W40=0,0,W41) -> 57.8
B42: ='01jan'!B42 -> 10 | C42: ='01jan'!C42 -> 20 | D42: Embalagens
B43: =IF(H52=0,0,IF(H52>1,W53)) -> 49.28 | D43: 7:30 a 12:00 | F43: 13:00 a 17:18 | H43: 45293 | L43: =L31 -> Justificativa por não ter conseguido produzir a demanda. Preencher esta coluna quando a coluna ao lado "Faltaram", não estiver com "0"
D44: =D32 -> Prod. | E44: =E32 -> Func. | F44: =F32 -> Prod. | G44: =G32 -> Func. | H44: =H32 -> Qtd. | I44: =I32 -> Méd Func. | J44: =J32 -> Méd. Prod.
...

Sheet 03fev
M2: =TODAY() -> 46034 | W2: 29
B6: ='01jan'!B6 -> 31 | C6: ='01jan'!C6 -> 32 | D6: Celula A
B7: =IF(H16=0,0,IF(H16>=1,W17)) -> 25.909263 | D7: 7:30 a 12:00 | F7: 13:00 a 17:18 | H7: =C10 -> 45691 | L7: Justificativa por não ter conseguido produzir a demanda. Preencher esta coluna quando a coluna ao lado "Faltaram", não estiver com "0"
D8: Prod. | E8: Func. | F8: =D8 -> Prod. | G8: =E8 -> Func. | H8: Qtd. | I8: Méd Func. | J8: Méd. Prod.
B9: Produtividade Média | K9: Não | T9: Data | U9: =H8 -> Qtd. | V9: =I8 -> Méd Func. | W9: Produtividade Diária
B10: Seg | C10: ='27jan'!C15+2 -> 45691 | D10: 62 | E10: 5.5 | F10: 42 | G10: 5 | H10: =D10+F10 -> 104 | I10: =IF(H10=0,0,AVERAGE(E10,G10)) -> 5.25 | J10: =IF(H10=0,0,H10/I10) -> 19.809524 | K10: =IF(#REF!<>0,"Não","") -> #REF! | T10: =C10 -> 45691 | U10: =H10 -> 104 | V10: =I10 -> 5.25 | W10: =J10 -> 19.809524 | X10: =IF(W10=0," ",IF(W10>1,1,)) -> 1
B11: Ter | C11: =C10+1 -> 45692 | D11: 153 | E11: 8 | F11: 47 | G11: 8 | H11: =D11+F11 -> 200 | I11: =IF(H11=0,0,AVERAGE(E11,G11)) -> 8 | J11: =IF(H11=0,0,H11/I11) -> 25 | K11: =IF(#REF!<>0,"Não","") -> #REF! | T11: =C11 -> 45692 | U11: =H11 -> 200 | V11: =I11 -> 8 | W11: =J11 -> 25 | X11: =IF(W11=0," ",IF(W11>1,1,)) -> 1
B12: Qua | C12: =C11+1 -> 45693 | D12: 81 | E12: 5.5 | F12: 80 | G12: 5 | H12: =D12+F12 -> 161 | I12: =IF(H12=0,0,AVERAGE(E12,G12)) -> 5.25 | J12: =IF(H12=0,0,H12/I12) -> 30.666667 | K12: =IF(#REF!<>0,"Não","") -> #REF! | T12: =C12 -> 45693 | U12: =H12 -> 161 | V12: =I12 -> 5.25 | W12: =J12 -> 30.666667 | X12: =IF(W12=0," ",IF(W12>1,1,)) -> 1
B13: Qui | C13: =C12+1 -> 45694 | D13: 70 | E13: 5.5 | F13: 94 | G13: 6 | H13: =D13+F13 -> 164 | I13: =IF(H13=0,0,AVERAGE(E13,G13)) -> 5.75 | J13: =IF(H13=0,0,H13/I13) -> 28.521739 | K13: =IF(#REF!<>0,"Não","") -> #REF! | T13: =C13 -> 45694 | U13: =H13 -> 164 | V13: =I13 -> 5.75 | W13: =J13 -> 28.521739 | X13: =IF(W13=0," ",IF(W13>1,1,)) -> 1
B14: Sex | C14: =C13+1 -> 45695 | D14: 98 | E14: 7.5 | F14: 100 | G14: 8 | H14: =D14+F14 -> 198 | I14: =IF(H14=0,0,AVERAGE(E14,G14)) -> 7.75 | J14: =IF(H14=0,0,H14/I14) -> 25.548387 | K14: =IF(#REF!<>0,"Não","") -> #REF! | T14: =C14 -> 45695 | U14: =H14 -> 198 | V14: =I14 -> 7.75 | W14: =J14 -> 25.548387 | X14: =IF(W14=0," ",IF(W14>1,1,)) -> 1
B15: SAb | C15: =C14+1 -> 45696 | H15: =D15+F15 -> 0 | I15: =IF(H15=0,0,AVERAGE(E15,G15)) -> 0 | J15: =IF(H15=0,0,H15/I15) -> 0
B16: Total Geral | D16: =SUM(D10:D15) -> 464 | E16: =IF(SUM(E10:E15)=0,0,AVERAGE(E10:E15)) -> 6.4 | F16: =SUM(F10:F15) -> 363 | G16: =IF(SUM(G10:G15)=0,0,AVERAGE(G10:G15)) -> 6.4 | H16: =D16+F16 -> 827 | I16: =IF(H16=0,0,AVERAGE(E16,G16)) -> 6.4 | J16: =IF(H16=0,0,H16/I16) -> 129.21875 | U16: =D16+F16 -> 827 | V16: =SUM(V10:V14) -> 32 | W16: =SUM(W10:W14) -> 129.54632 | X16: =COUNT(X10:X14) -> 5
W17: =W16/X16 -> 25.909263 | X17: =IF(W16=0,0,W17) -> 25.909263
B18: ='01jan'!B18 -> 9 | C18: ='01jan'!C18 -> 20 | D18: Consertos de Portas
B19: =IF(H28=0,0,IF(H28>=1,W29)) -> 10 | D19: 7:30 a 12:00 | F19: 13:00 a 17:18 | H19: =C22 -> 45691 | L19: =L7 -> Justificativa por não ter conseguido produzir a demanda. Preencher esta coluna quando a coluna ao lado "Faltaram", não estiver com "0"
D20: =D8 -> Prod. | E20: =E8 -> Func. | F20: =D20 -> Prod. | G20: =E20 -> Func. | H20: =H8 -> Qtd. | I20: =I8 -> Méd Func. | J20: =J8 -> Méd. Prod.
B21: =B9 -> Produtividade Média | K21: Não | T21: =T9 -> Data | U21: =U9 -> Qtd. | V21: =V9 -> Méd Func. | W21: =W9 -> Produtividade Diária
B22: =B10 -> Seg | C22: =C10 -> 45691 | D22: 4 | E22: 0.5 | F22: 3 | G22: 0.5 | H22: =D22+F22 -> 7 | I22: =IF(H22=0,0,AVERAGE(E22,G22)) -> 0.5 | J22: =IF(H22=0,0,H22/I22) -> 14 | K22: =IF(#REF!<>0,"Não","") -> #REF! | T22: =C22 -> 45691 | U22: =H22 -> 7 | V22: =I22 -> 0.5 | W22: =J22 -> 14 | X22: =IF(W22=0," ",IF(W22>1,1,)) -> 1
B23: =B11 -> Ter | C23: =C11 -> 45692 | D23: 3 | E23: 0.75 | F23: 0 | G23: 0 | H23: =D23+F23 -> 3 | I23: =IF(H23=0,0,AVERAGE(E23,G23)) -> 0.375 | J23: =IF(H23=0,0,H23/I23) -> 8 | K23: =IF(#REF!<>0,"Não","") -> #REF! | T23: =C23 -> 45692 | U23: =H23 -> 3 | V23: =I23 -> 0.375 | W23: =J23 -> 8 | X23: =IF(W23=0," ",IF(W23>1,1,)) -> 1
B24: =B12 -> Qua | C24: =C12 -> 45693 | D24: 3 | E24: 0.75 | F24: 3 | G24: 0.75 | H24: =D24+F24 -> 6 | I24: =IF(H24=0,0,AVERAGE(E24,G24)) -> 0.75 | J24: =IF(H24=0,0,H24/I24) -> 8 | K24: =IF(#REF!<>0,"Não","") -> #REF! | T24: =C24 -> 45693 | U24: =H24 -> 6 | V24: =I24 -> 0.75 | W24: =J24 -> 8 | X24: =IF(W24=0," ",IF(W24>1,1,)) -> 1
B25: =B13 -> Qui | C25: =C13 -> 45694 | D25: 3 | E25: 0.75 | F25: 3 | G25: 0.75 | H25: =D25+F25 -> 6 | I25: =IF(H25=0,0,AVERAGE(E25,G25)) -> 0.75 | J25: =IF(H25=0,0,H25/I25) -> 8 | K25: =IF(#REF!<>0,"Não","") -> #REF! | T25: =C25 -> 45694 | U25: =H25 -> 6 | V25: =I25 -> 0.75 | W25: =J25 -> 8 | X25: =IF(W25=0," ",IF(W25>1,1,)) -> 1
B26: =B14 -> Sex | C26: =C14 -> 45695 | D26: 1 | E26: 0.25 | F26: 2 | G26: 0.25 | H26: =D26+F26 -> 3 | I26: =IF(H26=0,0,AVERAGE(E26,G26)) -> 0.25 | J26: =IF(H26=0,0,H26/I26) -> 12 | K26: =IF(#REF!<>0,"Não","") -> #REF! | T26: =C26 -> 45695 | U26: =H26 -> 3 | V26: =I26 -> 0.25 | W26: =J26 -> 12 | X26: =IF(W26=0," ",IF(W26>1,1,)) -> 1
B27: =B15 -> SAb | C27: =C15 -> 45696 | H27: =D27+F27 -> 0 | I27: =IF(H27=0,0,AVERAGE(E27,G27)) -> 0 | J27: =IF(H27=0,0,H27/I27) -> 0
B28: =B16 -> Total Geral | D28: =SUM(D22:D27) -> 14 | E28: =IF(SUM(E22:E27)=0,0,AVERAGE(E22:E27)) -> 0.6 | F28: =SUM(F22:F27) -> 11 | G28: =IF(SUM(G22:G27)=0,0,AVERAGE(G22:G27)) -> 0.45 | H28: =D28+F28 -> 25 | I28: =AVERAGE(I22:I26) -> 0.525 | J28: =IF(H28=0,0,H28/I28) -> 47.619048 | U28: =D28+F28 -> 25 | V28: =SUM(V22:V26) -> 2.625 | W28: =SUM(W22:W26) -> 50 | X28: =COUNT(X22:X26) -> 5
W29: =W28/X28 -> 10 | X29: =IF(W28=0,0,W29) -> 10
B30: ='01jan'!B30 -> 40 | C30: ='01jan'!C30 -> 45 | D30: Folhas Frisadas
B31: =IF(H40=0,0,IF(H40>=1,W41)) -> 46.4 | D31: 7:30 a 12:00 | F31: 13:00 a 17:18 | H31: =C34 -> 45691 | L31: =L19 -> Justificativa por não ter conseguido produzir a demanda. Preencher esta coluna quando a coluna ao lado "Faltaram", não estiver com "0"
D32: =D20 -> Prod. | E32: =E20 -> Func. | F32: =D32 -> Prod. | G32: =E32 -> Func. | H32: =H20 -> Qtd. | I32: =I20 -> Méd Func. | J32: =J20 -> Méd. Prod.
B33: Produtividade Média | K33: Não | T33: =T21 -> Data | U33: =U21 -> Qtd. | V33: =V21 -> Méd Func. | W33: =W21 -> Produtividade Diária
B34: =B22 -> Seg | C34: =C10 -> 45691 | D34: 10 | E34: 0.25 | F34: 0 | G34: 0 | H34: =D34+F34 -> 10 | I34: =IF(H34=0,0,AVERAGE(E34,G34)) -> 0.125 | J34: =IF(H34=0,0,H34/I34) -> 80 | K34: =IF(#REF!<>0,"Não","") -> #REF! | T34: =C34 -> 45691 | U34: =H34 -> 10 | V34: =I34 -> 0.125 | W34: =J34 -> 80 | X34: =IF(W34=0," ",IF(W34>1,1,)) -> 1
B35: =B23 -> Ter | C35: =C11 -> 45692 | D35: 0 | E35: 0 | F35: 0 | G35: 0 | H35: =D35+F35 -> 0 | I35: =IF(H35=0,0,AVERAGE(E35,G35)) -> 0 | J35: =IF(H35=0,0,H35/I35) -> 0 | K35: =IF(#REF!<>0,"Não","") -> #REF! | T35: =C35 -> 45692 | U35: =H35 -> 0 | V35: =I35 -> 0 | W35: =J35 -> 0 | X35: =IF(W35=0," ",IF(W35>1,1,))
B36: =B24 -> Qua | C36: =C12 -> 45693 | D36: 5 | E36: 0.25 | F36: 11 | G36: 1 | H36: =D36+F36 -> 16 | I36: =IF(H36=0,0,AVERAGE(E36,G36)) -> 0.625 | J36: =IF(H36=0,0,H36/I36) -> 25.6 | K36: =IF(#REF!<>0,"Não","") -> #REF! | T36: =C36 -> 45693 | U36: =H36 -> 16 | V36: =I36 -> 0.625 | W36: =J36 -> 25.6 | X36: =IF(W36=0," ",IF(W36>1,1,)) -> 1
B37: =B25 -> Qui | C37: =C13 -> 45694 | D37: 27 | E37: 1 | F37: 15 | G37: 0.75 | H37: =D37+F37 -> 42 | I37: =IF(H37=0,0,AVERAGE(E37,G37)) -> 0.875 | J37: =IF(H37=0,0,H37/I37) -> 48 | K37: =IF(#REF!<>0,"Não","") -> #REF! | T37: =C37 -> 45694 | U37: =H37 -> 42 | V37: =I37 -> 0.875 | W37: =J37 -> 48 | X37: =IF(W37=0," ",IF(W37>1,1,)) -> 1
B38: =B26 -> Sex | C38: =C14 -> 45695 | D38: 0 | E38: 0 | F38: 4 | G38: 0.25 | H38: =D38+F38 -> 4 | I38: =IF(H38=0,0,AVERAGE(E38,G38)) -> 0.125 | J38: =IF(H38=0,0,H38/I38) -> 32 | K38: =IF(#REF!<>0,"Não","") -> #REF! | T38: =C38 -> 45695 | U38: =H38 -> 4 | V38: =I38 -> 0.125 | W38: =J38 -> 32 | X38: =IF(W38=0," ",IF(W38>1,1,)) -> 1
B39: =B27 -> SAb | C39: =C15 -> 45696 | H39: =D39+F39 -> 0 | I39: =IF(H39=0,0,AVERAGE(E39,G39)) -> 0 | J39: =IF(H39=0,0,H39/I39) -> 0
B40: =B28 -> Total Geral | D40: =SUM(D34:D39) -> 42 | E40: =IF(SUM(E34:E39)=0,0,AVERAGE(E34:E39)) -> 0.3 | F40: =SUM(F34:F39) -> 30 | G40: =IF(SUM(G34:G39)=0,0,AVERAGE(G34:G39)) -> 0.4 | H40: =D40+F40 -> 72 | I40: =AVERAGE(I34:I38) -> 0.35 | J40: 0 | U40: =D40+F40 -> 72 | V40: =SUM(V34:V38) -> 1.75 | W40: =SUM(W34:W38) -> 185.6 | X40: =COUNT(X34:X38) -> 4
W41: =W40/X40 -> 46.4 | X41: =IF(W40=0,0,W41) -> 46.4
B42: ='01jan'!B42 -> 10 | C42: ='01jan'!C42 -> 20 | D42: Embalagens
B43: =IF(H52=0,0,IF(H52>1,W53)) -> 36.653333 | D43: 7:30 a 12:00 | F43: 13:00 a 17:18 | H43: =C46 -> 45691 | L43: =L31 -> Justificativa por não ter conseguido produzir a demanda. Preencher esta coluna quando a coluna ao lado "Faltaram", não estiver com "0"
D44: =D32 -> Prod. | E44: =E32 -> Func. | F44: =F32 -> Prod. | G44: =G32 -> Func. | H44: =H32 -> Qtd. | I44: =I32 -> Méd Func. | J44: =J32 -> Méd. Prod.
...

Sheet 10fev
M2: =TODAY() -> 46034 | W2: 29
B6: ='01jan'!B6 -> 31 | C6: ='01jan'!C6 -> 32 | D6: Celula A
B7: =IF(H16=0,0,IF(H16>=1,W17)) -> 25.459615 | D7: 7:30 a 12:00 | F7: 13:00 a 17:18 | H7: =C10 -> 45698 | L7: Justificativa por não ter conseguido produzir a demanda. Preencher esta coluna quando a coluna ao lado "Faltaram", não estiver com "0"
D8: Prod. | E8: Func. | F8: =D8 -> Prod. | G8: =E8 -> Func. | H8: Qtd. | I8: Méd Func. | J8: Méd. Prod.
B9: Produtividade Média | K9: Não | T9: Data | U9: =H8 -> Qtd. | V9: =I8 -> Méd Func. | W9: Produtividade Diária
B10: Seg | C10: ='03fev'!C15+2 -> 45698 | D10: 104 | E10: 7 | F10: 85 | G10: 7 | H10: =D10+F10 -> 189 | I10: =IF(H10=0,0,AVERAGE(E10,G10)) -> 7 | J10: =IF(H10=0,0,H10/I10) -> 27 | K10: =IF(#REF!<>0,"Não","") -> #REF! | T10: =C10 -> 45698 | U10: =H10 -> 189 | V10: =I10 -> 7 | W10: =J10 -> 27 | X10: =IF(W10=0," ",IF(W10>1,1,)) -> 1
B11: Ter | C11: =C10+1 -> 45699 | D11: 93 | E11: 7 | F11: 63 | G11: 6 | H11: =D11+F11 -> 156 | I11: =IF(H11=0,0,AVERAGE(E11,G11)) -> 6.5 | J11: =IF(H11=0,0,H11/I11) -> 24 | K11: =IF(#REF!<>0,"Não","") -> #REF! | T11: =C11 -> 45699 | U11: =H11 -> 156 | V11: =I11 -> 6.5 | W11: =J11 -> 24 | X11: =IF(W11=0," ",IF(W11>1,1,)) -> 1
B12: Qua | C12: =C11+1 -> 45700 | D12: 103 | E12: 6.5 | F12: 85 | G12: 6.5 | H12: =D12+F12 -> 188 | I12: =IF(H12=0,0,AVERAGE(E12,G12)) -> 6.5 | J12: =IF(H12=0,0,H12/I12) -> 28.923077 | K12: =IF(#REF!<>0,"Não","") -> #REF! | T12: =C12 -> 45700 | U12: =H12 -> 188 | V12: =I12 -> 6.5 | W12: =J12 -> 28.923077 | X12: =IF(W12=0," ",IF(W12>1,1,)) -> 1
B13: Qui | C13: =C12+1 -> 45701 | D13: 56 | E13: 6 | F13: 58 | G13: 6 | H13: =D13+F13 -> 114 | I13: =IF(H13=0,0,AVERAGE(E13,G13)) -> 6 | J13: =IF(H13=0,0,H13/I13) -> 19 | K13: =IF(#REF!<>0,"Não","") -> #REF! | T13: =C13 -> 45701 | U13: =H13 -> 114 | V13: =I13 -> 6 | W13: =J13 -> 19 | X13: =IF(W13=0," ",IF(W13>1,1,)) -> 1
B14: Sex | C14: =C13+1 -> 45702 | D14: 109 | E14: 8 | F14: 118 | G14: 8 | H14: =D14+F14 -> 227 | I14: =IF(H14=0,0,AVERAGE(E14,G14)) -> 8 | J14: =IF(H14=0,0,H14/I14) -> 28.375 | K14: =IF(#REF!<>0,"Não","") -> #REF! | T14: =C14 -> 45702 | U14: =H14 -> 227 | V14: =I14 -> 8 | W14: =J14 -> 28.375 | X14: =IF(W14=0," ",IF(W14>1,1,)) -> 1
B15: SAb | C15: =C14+1 -> 45703 | H15: =D15+F15 -> 0 | I15: =IF(H15=0,0,AVERAGE(E15,G15)) -> 0 | J15: =IF(H15=0,0,H15/I15) -> 0
B16: Total Geral | D16: =SUM(D10:D15) -> 465 | E16: =IF(SUM(E10:E15)=0,0,AVERAGE(E10:E15)) -> 6.9 | F16: =SUM(F10:F15) -> 409 | G16: =IF(SUM(G10:G15)=0,0,AVERAGE(G10:G15)) -> 6.7 | H16: =D16+F16 -> 874 | I16: =IF(H16=0,0,AVERAGE(E16,G16)) -> 6.8 | J16: =IF(H16=0,0,H16/I16) -> 128.52941 | U16: =D16+F16 -> 874 | V16: =SUM(V10:V14) -> 34 | W16: =SUM(W10:W14) -> 127.29808 | X16: =COUNT(X10:X14) -> 5
W17: =W16/X16 -> 25.459615 | X17: =IF(W16=0,0,W17) -> 25.459615
B18: ='01jan'!B18 -> 9 | C18: ='01jan'!C18 -> 20 | D18: Consertos de Portas
B19: =IF(H28=0,0,IF(H28>=1,W29)) -> 13.452381 | D19: 7:30 a 12:00 | F19: 13:00 a 17:18 | H19: =C22 -> 45698 | L19: =L7 -> Justificativa por não ter conseguido produzir a demanda. Preencher esta coluna quando a coluna ao lado "Faltaram", não estiver com "0"
D20: =D8 -> Prod. | E20: =E8 -> Func. | F20: =D20 -> Prod. | G20: =E20 -> Func. | H20: =H8 -> Qtd. | I20: =I8 -> Méd Func. | J20: =J8 -> Méd. Prod.
B21: =B9 -> Produtividade Média | K21: Não | T21: =T9 -> Data | U21: =U9 -> Qtd. | V21: =V9 -> Méd Func. | W21: =W9 -> Produtividade Diária
B22: =B10 -> Seg | C22: =C10 -> 45698 | D22: 5 | E22: 0.75 | F22: 3 | G22: 1 | H22: =D22+F22 -> 8 | I22: =IF(H22=0,0,AVERAGE(E22,G22)) -> 0.875 | J22: =IF(H22=0,0,H22/I22) -> 9.1428571 | K22: =IF(#REF!<>0,"Não","") -> #REF! | T22: =C22 -> 45698 | U22: =H22 -> 8 | V22: =I22 -> 0.875 | W22: =J22 -> 9.1428571 | X22: =IF(W22=0," ",IF(W22>1,1,)) -> 1
B23: =B11 -> Ter | C23: =C11 -> 45699 | D23: 6 | E23: 1 | F23: 4 | G23: 1 | H23: =D23+F23 -> 10 | I23: =IF(H23=0,0,AVERAGE(E23,G23)) -> 1 | J23: =IF(H23=0,0,H23/I23) -> 10 | K23: =IF(#REF!<>0,"Não","") -> #REF! | T23: =C23 -> 45699 | U23: =H23 -> 10 | V23: =I23 -> 1 | W23: =J23 -> 10 | X23: =IF(W23=0," ",IF(W23>1,1,)) -> 1
B24: =B12 -> Qua | C24: =C12 -> 45700 | D24: 0 | E24: 0 | F24: 0 | G24: 0 | H24: =D24+F24 -> 0 | I24: =IF(H24=0,0,AVERAGE(E24,G24)) -> 0 | J24: =IF(H24=0,0,H24/I24) -> 0 | K24: =IF(#REF!<>0,"Não","") -> #REF! | T24: =C24 -> 45700 | U24: =H24 -> 0 | V24: =I24 -> 0 | W24: =J24 -> 0 | X24: =IF(W24=0," ",IF(W24>1,1,))
B25: =B13 -> Qui | C25: =C13 -> 45701 | D25: 2 | E25: 0.25 | F25: 0 | G25: 0 | H25: =D25+F25 -> 2 | I25: =IF(H25=0,0,AVERAGE(E25,G25)) -> 0.125 | J25: =IF(H25=0,0,H25/I25) -> 16 | K25: =IF(#REF!<>0,"Não","") -> #REF! | T25: =C25 -> 45701 | U25: =H25 -> 2 | V25: =I25 -> 0.125 | W25: =J25 -> 16 | X25: =IF(W25=0," ",IF(W25>1,1,)) -> 1
B26: =B14 -> Sex | C26: =C14 -> 45702 | D26: 0 | E26: 0 | F26: 7 | G26: 0.75 | H26: =D26+F26 -> 7 | I26: =IF(H26=0,0,AVERAGE(E26,G26)) -> 0.375 | J26: =IF(H26=0,0,H26/I26) -> 18.666667 | K26: =IF(#REF!<>0,"Não","") -> #REF! | T26: =C26 -> 45702 | U26: =H26 -> 7 | V26: =I26 -> 0.375 | W26: =J26 -> 18.666667 | X26: =IF(W26=0," ",IF(W26>1,1,)) -> 1
B27: =B15 -> SAb | C27: =C15 -> 45703 | H27: =D27+F27 -> 0 | I27: =IF(H27=0,0,AVERAGE(E27,G27)) -> 0 | J27: =IF(H27=0,0,H27/I27) -> 0
B28: =B16 -> Total Geral | D28: =SUM(D22:D27) -> 13 | E28: =IF(SUM(E22:E27)=0,0,AVERAGE(E22:E27)) -> 0.4 | F28: =SUM(F22:F27) -> 14 | G28: =IF(SUM(G22:G27)=0,0,AVERAGE(G22:G27)) -> 0.55 | H28: =D28+F28 -> 27 | I28: =AVERAGE(I22:I26) -> 0.475 | J28: =IF(H28=0,0,H28/I28) -> 56.842105 | U28: =D28+F28 -> 27 | V28: =SUM(V22:V26) -> 2.375 | W28: =SUM(W22:W26) -> 53.809524 | X28: =COUNT(X22:X26) -> 4
W29: =W28/X28 -> 13.452381 | X29: =IF(W28=0,0,W29) -> 13.452381
B30: ='01jan'!B30 -> 40 | C30: ='01jan'!C30 -> 45 | D30: Folhas Frisadas
B31: =IF(H40=0,0,IF(H40>=1,W41)) -> 45 | D31: 7:30 a 12:00 | F31: 13:00 a 17:18 | H31: =C34 -> 45698 | L31: =L19 -> Justificativa por não ter conseguido produzir a demanda. Preencher esta coluna quando a coluna ao lado "Faltaram", não estiver com "0"
D32: =D20 -> Prod. | E32: =E20 -> Func. | F32: =D32 -> Prod. | G32: =E32 -> Func. | H32: =H20 -> Qtd. | I32: =I20 -> Méd Func. | J32: =J20 -> Méd. Prod.
B33: Produtividade Média | K33: Não | T33: =T21 -> Data | U33: =U21 -> Qtd. | V33: =V21 -> Méd Func. | W33: =W21 -> Produtividade Diária
B34: =B22 -> Seg | C34: =C10 -> 45698 | D34: 15 | E34: 1 | F34: 24 | G34: 1 | H34: =D34+F34 -> 39 | I34: =IF(H34=0,0,AVERAGE(E34,G34)) -> 1 | J34: =IF(H34=0,0,H34/I34) -> 39 | K34: =IF(#REF!<>0,"Não","") -> #REF! | T34: =C34 -> 45698 | U34: =H34 -> 39 | V34: =I34 -> 1 | W34: =J34 -> 39 | X34: =IF(W34=0," ",IF(W34>1,1,)) -> 1
